Workbook

Sheet TOC
B1: KAROFI - MONTHLY SALES FORECAST
C3: Sales Forecast - Tháng 6 Tuần 0 | E3: Sales Forecast - Tháng 6 Tuần 1
B4: B1 | C4: Summary tháng | D4: B1 | E4: Summary tháng
B5: B1.1 | C5: MT | D5: B1.1 | E5: MT
B6: B1.1 | C6: GT1 | D6: B1.2 | E6: GT1
B7: B1.3 | C7: XK | D7: B1.3 | E7: XK
B8: B1.4 | C8: OEM | D8: B1.4 | E8: OEM
B9: B1.5 | C9: GT2 | D9: B1.5 | E9: GT2
B10: B1.6 | C10: Bán lẻ | D10: B1.6 | E10: Bán lẻ
B11: B1.7 | C11: Sales online | D11: B1.7 | E11: Sales online
B13: B5 | C13: Quy trình lập Sales forecast
B14: B6 | C14: Nguyên tắc và các giả định

Sheet B0.SUM (tuần 0)
A1: BẢNG 1: | B1: SALES FC - NGÀNH 1 (THÁNG 07.2026) | I1: Tháng 07- Sales FC | Q1: Tháng 08- Sales FC | Y1: Tháng 09- Sales FC | AG1: Tháng 10- Sales FC
I2: TỔNG | J2: MT | K2: XK | L2: MLT | M2: GT2 | N2: OEM | O2: Retail | P2: Online | Q2: TỔNG | R2: MT | S2: XK | T2: MLT | U2: GT2 | V2: OEM | W2: Retail | X2: Online | Y2: TỔNG | Z2: MT | AA2: XK | AB2: MLT | AC2: GT2 | AD2: OEM | AE2: Retail | AF2: Online | AG2: TỔNG | AH2: MT | AI2: XK | AJ2: MLT | AK2: GT2 | AL2: OEM | AM2: Retail | AN2: Online
A3: Ngày update: | B3: 46204 | G3: NHÓM 1 | H3: Máy TCM sx | I3: =SUM(J3:P3) -> 8205 | J3: =SUMIF($D$11:$D$2885,$H3,J$11:J$2885) -> 0 | K3: =SUMIF($D$11:$D$2885,$H3,K$11:K$2885) -> 3720 | L3: =SUMIF($D$11:$D$2885,$H3,L$11:L$2885) -> 0 | M3: =SUMIF($D$11:$D$2885,$H3,M$11:M$2885) -> 1400 | N3: =SUMIF($D$11:$D$2885,$H3,N$11:N$2885) -> 1430 | O3: =SUMIF($D$11:$D$2885,$H3,O$11:O$2885) -> 0 | P3: =SUMIF($D$11:$D$1062,$H3,P$11:P$1062) -> 1655 | Q3: =SUM(R3:X3) -> 11135 | R3: =SUMIF($D$11:$D$2885,$H3,R$11:R$2885) -> 0 | S3: =SUMIF($D$11:$D$2885,$H3,S$11:S$2885) -> 7075 | T3: =SUMIF($D$11:$D$2885,$H3,T$11:T$2885) -> 0 | U3: =SUMIF($D$11:$D$2885,$H3,U$11:U$2885) -> 1400 | V3: =SUMIF($D$11:$D$2885,$H3,V$11:V$2885) -> 1310 | W3: =SUMIF($D$11:$D$2885,$H3,W$11:W$2885) -> 0 | X3: =SUMIF($D$11:$D$1062,$H3,X$11:X$1062) -> 1350 | Y3: =SUM(Z3:AF3) -> 12011 | Z3: =SUMIF($D$11:$D$2885,$H3,Z$11:Z$2885) -> 0 | AA3: =SUMIF($D$11:$D$2885,$H3,AA$11:AA$2885) -> 7791 | AB3: =SUMIF($D$11:$D$2885,$H3,AB$11:AB$2885) -> 0 | AC3: =SUMIF($D$11:$D$2885,$H3,AC$11:AC$2885) -> 1450 | AD3: =SUMIF($D$11:$D$2885,$H3,AD$11:AD$2885) -> 1460 | AE3: =SUMIF($D$11:$D$2885,$H3,AE$11:AE$2885) -> 0 | AF3: =SUMIF($D$11:$D$1062,$H3,AF$11:AF$1062) -> 1310 | AG3: =SUM(AH3:AN3) -> 11840 | AH3: =SUMIF($D$11:$D$2885,$H3,AH$11:AH$2885) -> 0 | AI3: =SUMIF($D$11:$D$2885,$H3,AI$11:AI$2885) -> 8330 | AJ3: =SUMIF($D$11:$D$2885,$H3,AJ$11:AJ$2885) -> 0 | AK3: =SUMIF($D$11:$D$2885,$H3,AK$11:AK$2885) -> 1850 | AL3: =SUMIF($D$11:$D$2885,$H3,AL$11:AL$2885) -> 1660 | AM3: =SUMIF($D$11:$D$2885,$H3,AM$11:AM$2885) -> 0 | AN3: =SUMIF($D$11:$D$1062,$H3,AN$11:AN$1062) -> 0
A4: (Tuần 0 - tháng 07/2026) | G4: NHÓM 2 | H4: Máy nhập khẩu | I4: =SUM(J4:P4) -> 0 | J4: =SUMIF($D$11:$D$2885,$H4,J$11:J$2885) -> 0 | K4: =SUMIF($D$11:$D$2885,$H4,K$11:K$2885) -> 0 | L4: =SUMIF($D$11:$D$2885,$H4,L$11:L$2885) -> 0 | M4: =SUMIF($D$11:$D$2885,$H4,M$11:M$2885) -> 0 | N4: =SUMIF($D$11:$D$2885,$H4,N$11:N$2885) -> 0 | O4: =SUMIF($D$11:$D$2885,$H4,O$11:O$2885) -> 0 | P4: =SUMIF($D$11:$D$1062,$H4,P$11:P$1062) -> 0 | Q4: =SUM(R4:X4) -> 0 | R4: =SUMIF($D$11:$D$2885,$H4,R$11:R$2885) -> 0 | S4: =SUMIF($D$11:$D$2885,$H4,S$11:S$2885) -> 0 | T4: =SUMIF($D$11:$D$2885,$H4,T$11:T$2885) -> 0 | U4: =SUMIF($D$11:$D$2885,$H4,U$11:U$2885) -> 0 | V4: =SUMIF($D$11:$D$2885,$H4,V$11:V$2885) -> 0 | W4: =SUMIF($D$11:$D$2885,$H4,W$11:W$2885) -> 0 | X4: =SUMIF($D$11:$D$1062,$H4,X$11:X$1062) -> 0 | Y4: =SUM(Z4:AF4) -> 0 | Z4: =SUMIF($D$11:$D$2885,$H4,Z$11:Z$2885) -> 0 | AA4: =SUMIF($D$11:$D$2885,$H4,AA$11:AA$2885) -> 0 | AB4: =SUMIF($D$11:$D$2885,$H4,AB$11:AB$2885) -> 0 | AC4: =SUMIF($D$11:$D$2885,$H4,AC$11:AC$2885) -> 0 | AD4: =SUMIF($D$11:$D$2885,$H4,AD$11:AD$2885) -> 0 | AE4: =SUMIF($D$11:$D$2885,$H4,AE$11:AE$2885) -> 0 | AF4: =SUMIF($D$11:$D$1062,$H4,AF$11:AF$1062) -> 0 | AG4: =SUM(AH4:AN4) -> 0 | AH4: =SUMIF($D$11:$D$2885,$H4,AH$11:AH$2885) -> 0 | AI4: =SUMIF($D$11:$D$2885,$H4,AI$11:AI$2885) -> 0 | AJ4: =SUMIF($D$11:$D$2885,$H4,AJ$11:AJ$2885) -> 0 | AK4: =SUMIF($D$11:$D$2885,$H4,AK$11:AK$2885) -> 0 | AL4: =SUMIF($D$11:$D$2885,$H4,AL$11:AL$2885) -> 0 | AM4: =SUMIF($D$11:$D$2885,$H4,AM$11:AM$2885) -> 0 | AN4: =SUMIF($D$11:$D$1062,$H4,AN$11:AN$1062) -> 0
G5: NHÓM 3 | H5: Mockup | I5: =SUM(J5:P5) -> 0 | J5: =SUMIF($D$11:$D$2885,$H5,J$11:J$2885) -> 0 | K5: =SUMIF($D$11:$D$2885,$H5,K$11:K$2885) -> 0 | L5: =SUMIF($D$11:$D$2885,$H5,L$11:L$2885) -> 0 | M5: =SUMIF($D$11:$D$2885,$H5,M$11:M$2885) -> 0 | N5: =SUMIF($D$11:$D$2885,$H5,N$11:N$2885) -> 0 | O5: =SUMIF($D$11:$D$2885,$H5,O$11:O$2885) -> 0 | P5: =SUMIF($D$11:$D$1062,$H5,P$11:P$1062) -> 0 | Q5: =SUM(R5:X5) -> 0 | R5: =SUMIF($D$11:$D$2885,$H5,R$11:R$2885) -> 0 | S5: =SUMIF($D$11:$D$2885,$H5,S$11:S$2885) -> 0 | T5: =SUMIF($D$11:$D$2885,$H5,T$11:T$2885) -> 0 | U5: =SUMIF($D$11:$D$2885,$H5,U$11:U$2885) -> 0 | V5: =SUMIF($D$11:$D$2885,$H5,V$11:V$2885) -> 0 | W5: =SUMIF($D$11:$D$2885,$H5,W$11:W$2885) -> 0 | X5: =SUMIF($D$11:$D$1062,$H5,X$11:X$1062) -> 0 | Y5: =SUM(Z5:AF5) -> 0 | Z5: =SUMIF($D$11:$D$2885,$H5,Z$11:Z$2885) -> 0 | AA5: =SUMIF($D$11:$D$2885,$H5,AA$11:AA$2885) -> 0 | AB5: =SUMIF($D$11:$D$2885,$H5,AB$11:AB$2885) -> 0 | AC5: =SUMIF($D$11:$D$2885,$H5,AC$11:AC$2885) -> 0 | AD5: =SUMIF($D$11:$D$2885,$H5,AD$11:AD$2885) -> 0 | AE5: =SUMIF($D$11:$D$2885,$H5,AE$11:AE$2885) -> 0 | AF5: =SUMIF($D$11:$D$1062,$H5,AF$11:AF$1062) -> 0 | AG5: =SUM(AH5:AN5) -> 0 | AH5: =SUMIF($D$11:$D$2885,$H5,AH$11:AH$2885) -> 0 | AI5: =SUMIF($D$11:$D$2885,$H5,AI$11:AI$2885) -> 0 | AJ5: =SUMIF($D$11:$D$2885,$H5,AJ$11:AJ$2885) -> 0 | AK5: =SUMIF($D$11:$D$2885,$H5,AK$11:AK$2885) -> 0 | AL5: =SUMIF($D$11:$D$2885,$H5,AL$11:AL$2885) -> 0 | AM5: =SUMIF($D$11:$D$2885,$H5,AM$11:AM$2885) -> 0 | AN5: =SUMIF($D$11:$D$1062,$H5,AN$11:AN$1062) -> 0
G6: NHÓM 4 | H6: Lõi | I6: =SUM(J6:P6) -> 103479 | J6: =SUMIF($D$11:$D$2885,$H6,J$11:J$2885) -> 0 | K6: =SUMIF($D$11:$D$2885,$H6,K$11:K$2885) -> 101877 | L6: =SUMIF($D$11:$D$2885,$H6,L$11:L$2885) -> 0 | M6: =SUMIF($D$11:$D$2885,$H6,M$11:M$2885) -> 0 | N6: =SUMIF($D$11:$D$2885,$H6,N$11:N$2885) -> 0 | O6: =SUMIF($D$11:$D$2885,$H6,O$11:O$2885) -> 0 | P6: =SUMIF($D$11:$D$1062,$H6,P$11:P$1062) -> 1602 | Q6: =SUM(R6:X6) -> 45180 | R6: =SUMIF($D$11:$D$2885,$H6,R$11:R$2885) -> 0 | S6: =SUMIF($D$11:$D$2885,$H6,S$11:S$2885) -> 43340 | T6: =SUMIF($D$11:$D$2885,$H6,T$11:T$2885) -> 0 | U6: =SUMIF($D$11:$D$2885,$H6,U$11:U$2885) -> 0 | V6: =SUMIF($D$11:$D$2885,$H6,V$11:V$2885) -> 0 | W6: =SUMIF($D$11:$D$2885,$H6,W$11:W$2885) -> 0 | X6: =SUMIF($D$11:$D$1062,$H6,X$11:X$1062) -> 1840 | Y6: =SUM(Z6:AF6) -> 61020 | Z6: =SUMIF($D$11:$D$2885,$H6,Z$11:Z$2885) -> 0 | AA6: =SUMIF($D$11:$D$2885,$H6,AA$11:AA$2885) -> 59130 | AB6: =SUMIF($D$11:$D$2885,$H6,AB$11:AB$2885) -> 0 | AC6: =SUMIF($D$11:$D$2885,$H6,AC$11:AC$2885) -> 0 | AD6: =SUMIF($D$11:$D$2885,$H6,AD$11:AD$2885) -> 0 | AE6: =SUMIF($D$11:$D$2885,$H6,AE$11:AE$2885) -> 0 | AF6: =SUMIF($D$11:$D$1062,$H6,AF$11:AF$1062) -> 1890 | AG6: =SUM(AH6:AN6) -> 294033 | AH6: =SUMIF($D$11:$D$2885,$H6,AH$11:AH$2885) -> 0 | AI6: =SUMIF($D$11:$D$2885,$H6,AI$11:AI$2885) -> 292143 | AJ6: =SUMIF($D$11:$D$2885,$H6,AJ$11:AJ$2885) -> 0 | AK6: =SUMIF($D$11:$D$2885,$H6,AK$11:AK$2885) -> 0 | AL6: =SUMIF($D$11:$D$2885,$H6,AL$11:AL$2885) -> 0 | AM6: =SUMIF($D$11:$D$2885,$H6,AM$11:AM$2885) -> 0 | AN6: =SUMIF($D$11:$D$1062,$H6,AN$11:AN$1062) -> 1890
G7: NHÓM 5 | H7: Màng | I7: =SUM(J7:P7) -> 2630 | J7: =SUMIF($D$11:$D$2885,$H7,J$11:J$2885) -> 0 | K7: =SUMIF($D$11:$D$2885,$H7,K$11:K$2885) -> 2475 | L7: =SUMIF($D$11:$D$2885,$H7,L$11:L$2885) -> 0 | M7: =SUMIF($D$11:$D$2885,$H7,M$11:M$2885) -> 0 | N7: =SUMIF($D$11:$D$2885,$H7,N$11:N$2885) -> 0 | O7: =SUMIF($D$11:$D$2885,$H7,O$11:O$2885) -> 0 | P7: =SUMIF($D$11:$D$1062,$H7,P$11:P$1062) -> 155 | Q7: =SUM(R7:X7) -> 2162 | R7: =SUMIF($D$11:$D$2885,$H7,R$11:R$2885) -> 0 | S7: =SUMIF($D$11:$D$2885,$H7,S$11:S$2885) -> 1975 | T7: =SUMIF($D$11:$D$2885,$H7,T$11:T$2885) -> 0 | U7: =SUMIF($D$11:$D$2885,$H7,U$11:U$2885) -> 0 | V7: =SUMIF($D$11:$D$2885,$H7,V$11:V$2885) -> 0 | W7: =SUMIF($D$11:$D$2885,$H7,W$11:W$2885) -> 0 | X7: =SUMIF($D$11:$D$1062,$H7,X$11:X$1062) -> 187 | Y7: =SUM(Z7:AF7) -> 1637 | Z7: =SUMIF($D$11:$D$2885,$H7,Z$11:Z$2885) -> 0 | AA7: =SUMIF($D$11:$D$2885,$H7,AA$11:AA$2885) -> 1450 | AB7: =SUMIF($D$11:$D$2885,$H7,AB$11:AB$2885) -> 0 | AC7: =SUMIF($D$11:$D$2885,$H7,AC$11:AC$2885) -> 0 | AD7: =SUMIF($D$11:$D$2885,$H7,AD$11:AD$2885) -> 0 | AE7: =SUMIF($D$11:$D$2885,$H7,AE$11:AE$2885) -> 0 | AF7: =SUMIF($D$11:$D$1062,$H7,AF$11:AF$1062) -> 187 | AG7: =SUM(AH7:AN7) -> 2217 | AH7: =SUMIF($D$11:$D$2885,$H7,AH$11:AH$2885) -> 0 | AI7: =SUMIF($D$11:$D$2885,$H7,AI$11:AI$2885) -> 2030 | AJ7: =SUMIF($D$11:$D$2885,$H7,AJ$11:AJ$2885) -> 0 | AK7: =SUMIF($D$11:$D$2885,$H7,AK$11:AK$2885) -> 0 | AL7: =SUMIF($D$11:$D$2885,$H7,AL$11:AL$2885) -> 0 | AM7: =SUMIF($D$11:$D$2885,$H7,AM$11:AM$2885) -> 0 | AN7: =SUMIF($D$11:$D$1062,$H7,AN$11:AN$1062) -> 187
I8: =SUMPRODUCT(I11:I1916,$H$11:$H$1916) -> 19058770710 | J8: =SUMPRODUCT(J11:J1916,$H$11:$H$1916) -> 0 | K8: =SUMPRODUCT(K11:K1916,$H$11:$H$1916) -> 10527725363 | L8: =SUMPRODUCT(L11:L1916,$H$11:$H$1916) -> 0 | M8: =SUMPRODUCT(M11:M1916,$H$11:$H$1916) -> 0 | N8: =SUMPRODUCT(N11:N1916,$H$11:$H$1916) -> 8356029325 | O8: =SUMPRODUCT(O11:O1916,$H$11:$H$1916) -> 0 | P8: =SUMPRODUCT(P11:P1916,$H$11:$H$1916) -> 175016022 | ... AM8: =SUMPRODUCT(AM11:AM1916,$H$11:$H$1916) -> 0 | AN8: =SUMPRODUCT(AN11:AN762,$H$11:$H$762) -> 195099456
A9: Mã sp | B9: Tên sp | C9: Tên gọi tắt | D9: Nhóm | E9: Công nghệ | F9: Kênh | G9: Đ.quyền | H9: Giá bán BQ | I9: Tổng | J9: MT | K9: XK | L9: MLT | M9: GT2 | N9: OEM | O9: Retail | P9: Online | Q9: Tổng | R9: MT | S9: XK | T9: MLT | U9: GT2 | V9: OEM | W9: Retail | X9: Online | Y9: Tổng | Z9: MT | AA9: XK | AB9: MLT | AC9: GT2 | AD9: OEM | AE9: Retail | AF9: Online | AG9: Tổng | AH9: MT | AI9: XK | AJ9: MLT | AK9: GT2 | AL9: OEM | AM9: Retail | AN9: Online | AO9: LƯU Ý
I10: =SUBTOTAL(9,I11:I1902) -> 821861 | J10: =SUBTOTAL(9,J11:J1902) -> 0 | K10: =SUBTOTAL(9,K11:K1902) -> 146808 | L10: =SUBTOTAL(9,L11:L1902) -> 0 | M10: =SUBTOTAL(9,M11:M1902) -> 1400 | N10: =SUBTOTAL(9,N11:N1902) -> 652590 | O10: =SUBTOTAL(9,O11:O1902) -> 0 | P10: =SUBTOTAL(9,P11:P1902) -> 21063 | ... AM10: =SUBTOTAL(9,AM11:AM1902) -> 0
A11: 1001010040 | B11: Máy lọc nước KoriHome WPK-606 | C11: WPK-606 | D11: Máy TCM Sx | E11: 10L | F11: XK | H11: 3025631 | I11: =SUM(J11:P11) -> 100 | K11: =SUMIFS('B0.3.XK'!J:J,'B0.3.XK'!A:A,'B0.SUM (tuần 0)'!$A11) -> 100 | M11: =SUMIFS('B0.5.GT2'!K:K,'B0.5.GT2'!A:A,'B0.SUM (tuần 0)'!$A11) -> 0 | N11: =SUMIFS('B0.4.OEM'!J:J,'B0.4.OEM'!A:A,'B0.SUM (tuần 0)'!$A11) -> 0 | P11: =SUMIFS('B0.8.Online'!J:J,'B0.8.Online'!A:A,'B0.SUM (tuần 0)'!$A11) -> 0 | Q11: =SUM(R11:X11) -> 0 | S11: =SUMIFS('B0.3.XK'!K:K,'B0.3.XK'!A:A,'B0.SUM (tuần 0)'!$A11) -> 0 | U11: =SUMIFS('B0.5.GT2'!K:K,'B0.5.GT2'!A:A,'B0.SUM (tuần 0)'!$A11) -> 0 | V11: =SUMIFS('B0.4.OEM'!K:K,'B0.4.OEM'!A:A,'B0.SUM (tuần 0)'!$A11) -> 0 | X11: =SUMIFS('B0.8.Online'!K:K,'B0.8.Online'!A:A,'B0.SUM (tuần 0)'!$A11) -> 0 | Y11: =SUM(Z11:AF11) -> 0 | AA11: =SUMIFS('B0.3.XK'!L:L,'B0.3.XK'!A:A,'B0.SUM (tuần 0)'!$A11) -> 0 | AC11: =SUMIFS('B0.5.GT2'!L:L,'B0.5.GT2'!A:A,'B0.SUM (tuần 0)'!$A11) -> 0 | AD11: =SUMIFS('B0.4.OEM'!L:L,'B0.4.OEM'!A:A,'B0.SUM (tuần 0)'!$A11) -> 0 | AF11: =SUMIFS('B0.8.Online'!L:L,'B0.8.Online'!A:A,'B0.SUM (tuần 0)'!$A11) -> 0 | AG11: =SUM(AH11:AN11) -> 0 | AI11: =SUMIFS('B0.3.XK'!M:M,'B0.3.XK'!A:A,'B0.SUM (tuần 0)'!$A11) -> 0 | AK11: =SUMIFS('B0.5.GT2'!M:M,'B0.5.GT2'!A:A,'B0.SUM (tuần 0)'!$A11) -> 0 | AL11: =SUMIFS('B0.4.OEM'!M:M,'B0.4.OEM'!A:A,'B0.SUM (tuần 0)'!$A11) -> 0 | AN11: =SUMIFS('B0.8.Online'!M:M,'B0.8.Online'!A:A,'B0.SUM (tuần 0)'!$A11) -> 0 | AO11: Model clear tại nguyễn Kim | AP11: =SUMIFS('B1.SUM (tuần 4)'!$I:$I,'B1.SUM (tuần 4)'!$A:$A,'B0.SUM (tuần 0)'!$A11) -> 0 | AQ11: =I11-AP11 -> 100
A12: 1001020018 | B12: Bộ lọc thô 2 stages GRANDSAFE | C12: Prefilter2S10" | D12: Máy TCM Sx | E12: Bộ lọc thô | F12: XK | H12: 210479 | I12: =SUM(J12:P12) -> 0 | K12: =SUMIFS('B0.3.XK'!J:J,'B0.3.XK'!A:A,'B0.SUM (tuần 0)'!$A12) -> 0 | M12: =SUMIFS('B0.5.GT2'!K:K,'B0.5.GT2'!A:A,'B0.SUM (tuần 0)'!$A12) -> 0 | N12: =SUMIFS('B0.4.OEM'!J:J,'B0.4.OEM'!A:A,'B0.SUM (tuần 0)'!$A12) -> 0 | P12: =SUMIFS('B0.8.Online'!J:J,'B0.8.Online'!A:A,'B0.SUM (tuần 0)'!$A12) -> 0 | Q12: =SUM(R12:X12) -> 2 | S12: =SUMIFS('B0.3.XK'!K:K,'B0.3.XK'!A:A,'B0.SUM (tuần 0)'!$A12) -> 2 | U12: =SUMIFS('B0.5.GT2'!K:K,'B0.5.GT2'!A:A,'B0.SUM (tuần 0)'!$A12) -> 0 | V12: =SUMIFS('B0.4.OEM'!K:K,'B0.4.OEM'!A:A,'B0.SUM (tuần 0)'!$A12) -> 0 | X12: =SUMIFS('B0.8.Online'!K:K,'B0.8.Online'!A:A,'B0.SUM (tuần 0)'!$A12) -> 0 | Y12: =SUM(Z12:AF12) -> 0 | AA12: =SUMIFS('B0.3.XK'!L:L,'B0.3.XK'!A:A,'B0.SUM (tuần 0)'!$A12) -> 0 | AC12: =SUMIFS('B0.5.GT2'!L:L,'B0.5.GT2'!A:A,'B0.SUM (tuần 0)'!$A12) -> 0 | AD12: =SUMIFS('B0.4.OEM'!L:L,'B0.4.OEM'!A:A,'B0.SUM (tuần 0)'!$A12) -> 0 | AF12: =SUMIFS('B0.8.Online'!L:L,'B0.8.Online'!A:A,'B0.SUM (tuần 0)'!$A12) -> 0 | AG12: =SUM(AH12:AN12) -> 0 | AI12: =SUMIFS('B0.3.XK'!M:M,'B0.3.XK'!A:A,'B0.SUM (tuần 0)'!$A12) -> 0 | AK12: =SUMIFS('B0.5.GT2'!M:M,'B0.5.GT2'!A:A,'B0.SUM (tuần 0)'!$A12) -> 0 | AL12: =SUMIFS('B0.4.OEM'!M:M,'B0.4.OEM'!A:A,'B0.SUM (tuần 0)'!$A12) -> 0 | AN12: =SUMIFS('B0.8.Online'!M:M,'B0.8.Online'!A:A,'B0.SUM (tuần 0)'!$A12) -> 0 | AP12: =SUMIFS('B1.SUM (tuần 4)'!$I:$I,'B1.SUM (tuần 4)'!$A:$A,'B0.SUM (tuần 0)'!$A12) -> 0 | AQ12: =I12-AP12 -> 0
A13: 1001020019 | B13: Bộ lọc thô 1 stage GRANDSAFE | C13: Prefilter1S10" | D13: Máy TCM Sx | E13: Bộ lọc thô | F13: XK | H13: 152860 | I13: =SUM(J13:P13) -> 0 | K13: =SUMIFS('B0.3.XK'!J:J,'B0.3.XK'!A:A,'B0.SUM (tuần 0)'!$A13) -> 0 | M13: =SUMIFS('B0.5.GT2'!K:K,'B0.5.GT2'!A:A,'B0.SUM (tuần 0)'!$A13) -> 0 | N13: =SUMIFS('B0.4.OEM'!J:J,'B0.4.OEM'!A:A,'B0.SUM (tuần 0)'!$A13) -> 0 | P13: =SUMIFS('B0.8.Online'!J:J,'B0.8.Online'!A:A,'B0.SUM (tuần 0)'!$A13) -> 0 | Q13: =SUM(R13:X13) -> 0 | S13: =SUMIFS('B0.3.XK'!K:K,'B0.3.XK'!A:A,'B0.SUM (tuần 0)'!$A13) -> 0 | U13: =SUMIFS('B0.5.GT2'!K:K,'B0.5.GT2'!A:A,'B0.SUM (tuần 0)'!$A13) -> 0 | V13: =SUMIFS('B0.4.OEM'!K:K,'B0.4.OEM'!A:A,'B0.SUM (tuần 0)'!$A13) -> 0 | X13: =SUMIFS('B0.8.Online'!K:K,'B0.8.Online'!A:A,'B0.SUM (tuần 0)'!$A13) -> 0 | Y13: =SUM(Z13:AF13) -> 0 | AA13: =SUMIFS('B0.3.XK'!L:L,'B0.3.XK'!A:A,'B0.SUM (tuần 0)'!$A13) -> 0 | AC13: =SUMIFS('B0.5.GT2'!L:L,'B0.5.GT2'!A:A,'B0.SUM (tuần 0)'!$A13) -> 0 | AD13: =SUMIFS('B0.4.OEM'!L:L,'B0.4.OEM'!A:A,'B0.SUM (tuần 0)'!$A13) -> 0 | AF13: =SUMIFS('B0.8.Online'!L:L,'B0.8.Online'!A:A,'B0.SUM (tuần 0)'!$A13) -> 0 | AG13: =SUM(AH13:AN13) -> 0 | AI13: =SUMIFS('B0.3.XK'!M:M,'B0.3.XK'!A:A,'B0.SUM (tuần 0)'!$A13) -> 0 | AK13: =SUMIFS('B0.5.GT2'!M:M,'B0.5.GT2'!A:A,'B0.SUM (tuần 0)'!$A13) -> 0 | AL13: =SUMIFS('B0.4.OEM'!M:M,'B0.4.OEM'!A:A,'B0.SUM (tuần 0)'!$A13) -> 0 | AN13: =SUMIFS('B0.8.Online'!M:M,'B0.8.Online'!A:A,'B0.SUM (tuần 0)'!$A13) -> 0 | AO13: Hàng clear, CEO yêu cầu dừng mã | AP13: =SUMIFS('B1.SUM (tuần 4)'!$I:$I,'B1.SUM (tuần 4)'!$A:$A,'B0.SUM (tuần 0)'!$A13) -> 0 | AQ13: =I13-AP13 -> 0
A14: 1001020027 | B14: Bộ lọc thô 1 stage AQUALAND | C14: Prefilter1S10" | D14: Máy TCM Sx | E14: Bộ lọc thô | F14: XK | H14: 132865 | I14: =SUM(J14:P14) -> 0 | K14: =SUMIFS('B0.3.XK'!J:J,'B0.3.XK'!A:A,'B0.SUM (tuần 0)'!$A14) -> 0 | M14: =SUMIFS('B0.5.GT2'!K:K,'B0.5.GT2'!A:A,'B0.SUM (tuần 0)'!$A14) -> 0 | N14: =SUMIFS('B0.4.OEM'!J:J,'B0.4.OEM'!A:A,'B0.SUM (tuần 0)'!$A14) -> 0 | P14: =SUMIFS('B0.8.Online'!J:J,'B0.8.Online'!A:A,'B0.SUM (tuần 0)'!$A14) -> 0 | Q14: =SUM(R14:X14) -> 0 | S14: =SUMIFS('B0.3.XK'!K:K,'B0.3.XK'!A:A,'B0.SUM (tuần 0)'!$A14) -> 0 | U14: =SUMIFS('B0.5.GT2'!K:K,'B0.5.GT2'!A:A,'B0.SUM (tuần 0)'!$A14) -> 0 | V14: =SUMIFS('B0.4.OEM'!K:K,'B0.4.OEM'!A:A,'B0.SUM (tuần 0)'!$A14) -> 0 | X14: =SUMIFS('B0.8.Online'!K:K,'B0.8.Online'!A:A,'B0.SUM (tuần 0)'!$A14) -> 0 | Y14: =SUM(Z14:AF14) -> 0 | AA14: =SUMIFS('B0.3.XK'!L:L,'B0.3.XK'!A:A,'B0.SUM (tuần 0)'!$A14) -> 0 | AC14: =SUMIFS('B0.5.GT2'!L:L,'B0.5.GT2'!A:A,'B0.SUM (tuần 0)'!$A14) -> 0 | AD14: =SUMIFS('B0.4.OEM'!L:L,'B0.4.OEM'!A:A,'B0.SUM (tuần 0)'!$A14) -> 0 | AF14: =SUMIFS('B0.8.Online'!L:L,'B0.8.Online'!A:A,'B0.SUM (tuần 0)'!$A14) -> 0 | AG14: =SUM(AH14:AN14) -> 0 | AI14: =SUMIFS('B0.3.XK'!M:M,'B0.3.XK'!A:A,'B0.SUM (tuần 0)'!$A14) -> 0 | AK14: =SUMIFS('B0.5.GT2'!M:M,'B0.5.GT2'!A:A,'B0.SUM (tuần 0)'!$A14) -> 0 | AL14: =SUMIFS('B0.4.OEM'!M:M,'B0.4.OEM'!A:A,'B0.SUM (tuần 0)'!$A14) -> 0 | AN14: =SUMIFS('B0.8.Online'!M:M,'B0.8.Online'!A:A,'B0.SUM (tuần 0)'!$A14) -> 0 | AP14: =SUMIFS('B1.SUM (tuần 4)'!$I:$I,'B1.SUM (tuần 4)'!$A:$A,'B0.SUM (tuần 0)'!$A14) -> 0 | AQ14: =I14-AP14 -> 0
A15: 1001040396 | B15: Water purifier KAROFI S-s156 MT (KBA) | C15: S-S156 | D15: Máy TCM Sx | E15: BCN | F15: XK | H15: 5393516 | I15: =SUM(J15:P15) -> 0 | K15: =SUMIFS('B0.3.XK'!J:J,'B0.3.XK'!A:A,'B0.SUM (tuần 0)'!$A15) -> 0 | M15: =SUMIFS('B0.5.GT2'!K:K,'B0.5.GT2'!A:A,'B0.SUM (tuần 0)'!$A15) -> 0 | N15: =SUMIFS('B0.4.OEM'!J:J,'B0.4.OEM'!A:A,'B0.SUM (tuần 0)'!$A15) -> 0 | P15: =SUMIFS('B0.8.Online'!J:J,'B0.8.Online'!A:A,'B0.SUM (tuần 0)'!$A15) -> 0 | Q15: =SUM(R15:X15) -> 0 | S15: =SUMIFS('B0.3.XK'!K:K,'B0.3.XK'!A:A,'B0.SUM (tuần 0)'!$A15) -> 0 | U15: =SUMIFS('B0.5.GT2'!K:K,'B0.5.GT2'!A:A,'B0.SUM (tuần 0)'!$A15) -> 0 | V15: =SUMIFS('B0.4.OEM'!K:K,'B0.4.OEM'!A:A,'B0.SUM (tuần 0)'!$A15) -> 0 | X15: =SUMIFS('B0.8.Online'!K:K,'B0.8.Online'!A:A,'B0.SUM (tuần 0)'!$A15) -> 0 | Y15: =SUM(Z15:AF15) -> 0 | AA15: =SUMIFS('B0.3.XK'!L:L,'B0.3.XK'!A:A,'B0.SUM (tuần 0)'!$A15) -> 0 | AC15: =SUMIFS('B0.5.GT2'!L:L,'B0.5.GT2'!A:A,'B0.SUM (tuần 0)'!$A15) -> 0 | AD15: =SUMIFS('B0.4.OEM'!L:L,'B0.4.OEM'!A:A,'B0.SUM (tuần 0)'!$A15) -> 0 | AF15: =SUMIFS('B0.8.Online'!L:L,'B0.8.Online'!A:A,'B0.SUM (tuần 0)'!$A15) -> 0 | AG15: =SUM(AH15:AN15) -> 0 | AI15: =SUMIFS('B0.3.XK'!M:M,'B0.3.XK'!A:A,'B0.SUM (tuần 0)'!$A15) -> 0 | AK15: =SUMIFS('B0.5.GT2'!M:M,'B0.5.GT2'!A:A,'B0.SUM (tuần 0)'!$A15) -> 0 | AL15: =SUMIFS('B0.4.OEM'!M:M,'B0.4.OEM'!A:A,'B0.SUM (tuần 0)'!$A15) -> 0 | AN15: =SUMIFS('B0.8.Online'!M:M,'B0.8.Online'!A:A,'B0.SUM (tuần 0)'!$A15) -> 0 | AP15: =SUMIFS('B1.SUM (tuần 4)'!$I:$I,'B1.SUM (tuần 4)'!$A:$A,'B0.SUM (tuần 0)'!$A15) -> 0 | AQ15: =I15-AP15 -> 0
A16: 1001040483 | B16: Máy lọc nước KAROFI KAQ-X16 | C16: KAQ-X16 | D16: Máy TCM Sx | E16: 10L Tủ | F16: XK | H16: 2853039 | I16: =SUM(J16:P16) -> 0 | K16: =SUMIFS('B0.3.XK'!J:J,'B0.3.XK'!A:A,'B0.SUM (tuần 0)'!$A16) -> 0 | M16: =SUMIFS('B0.5.GT2'!K:K,'B0.5.GT2'!A:A,'B0.SUM (tuần 0)'!$A16) -> 0 | N16: =SUMIFS('B0.4.OEM'!J:J,'B0.4.OEM'!A:A,'B0.SUM (tuần 0)'!$A16) -> 0 | P16: =SUMIFS('B0.8.Online'!J:J,'B0.8.Online'!A:A,'B0.SUM (tuần 0)'!$A16) -> 0 | Q16: =SUM(R16:X16) -> 0 | S16: =SUMIFS('B0.3.XK'!K:K,'B0.3.XK'!A:A,'B0.SUM (tuần 0)'!$A16) -> 0 | U16: =SUMIFS('B0.5.GT2'!K:K,'B0.5.GT2'!A:A,'B0.SUM (tuần 0)'!$A16) -> 0 | V16: =SUMIFS('B0.4.OEM'!K:K,'B0.4.OEM'!A:A,'B0.SUM (tuần 0)'!$A16) -> 0 | X16: =SUMIFS('B0.8.Online'!K:K,'B0.8.Online'!A:A,'B0.SUM (tuần 0)'!$A16) -> 0 | Y16: =SUM(Z16:AF16) -> 0 | AA16: =SUMIFS('B0.3.XK'!L:L,'B0.3.XK'!A:A,'B0.SUM (tuần 0)'!$A16) -> 0 | AC16: =SUMIFS('B0.5.GT2'!L:L,'B0.5.GT2'!A:A,'B0.SUM (tuần 0)'!$A16) -> 0 | AD16: =SUMIFS('B0.4.OEM'!L:L,'B0.4.OEM'!A:A,'B0.SUM (tuần 0)'!$A16) -> 0 | AF16: =SUMIFS('B0.8.Online'!L:L,'B0.8.Online'!A:A,'B0.SUM (tuần 0)'!$A16) -> 0 | AG16: =SUM(AH16:AN16) -> 0 | AI16: =SUMIFS('B0.3.XK'!M:M,'B0.3.XK'!A:A,'B0.SUM (tuần 0)'!$A16) -> 0 | AK16: =SUMIFS('B0.5.GT2'!M:M,'B0.5.GT2'!A:A,'B0.SUM (tuần 0)'!$A16) -> 0 | AL16: =SUMIFS('B0.4.OEM'!M:M,'B0.4.OEM'!A:A,'B0.SUM (tuần 0)'!$A16) -> 0 | AN16: =SUMIFS('B0.8.Online'!M:M,'B0.8.Online'!A:A,'B0.SUM (tuần 0)'!$A16) -> 0 | AP16: =SUMIFS('B1.SUM (tuần 4)'!$I:$I,'B1.SUM (tuần 4)'!$A:$A,'B0.SUM (tuần 0)'!$A16) -> 0 | AQ16: =I16-AP16 -> 0
A17: 1001040513 | B17: Máy lọc nước nóng lạnh KAROFI HCV-208RO | C17: HCV-208RO | D17: Máy TCM Sx | E17: Block | F17: XK | H17: 2044274 | I17: =SUM(J17:P17) -> 30 | K17: =SUMIFS('B0.3.XK'!J:J,'B0.3.XK'!A:A,'B0.SUM (tuần 0)'!$A17) -> 30 | M17: =SUMIFS('B0.5.GT2'!K:K,'B0.5.GT2'!A:A,'B0.SUM (tuần 0)'!$A17) -> 0 | N17: =SUMIFS('B0.4.OEM'!J:J,'B0.4.OEM'!A:A,'B0.SUM (tuần 0)'!$A17) -> 0 | P17: =SUMIFS('B0.8.Online'!J:J,'B0.8.Online'!A:A,'B0.SUM (tuần 0)'!$A17) -> 0 | Q17: =SUM(R17:X17) -> 0 | S17: =SUMIFS('B0.3.XK'!K:K,'B0.3.XK'!A:A,'B0.SUM (tuần 0)'!$A17) -> 0 | U17: =SUMIFS('B0.5.GT2'!K:K,'B0.5.GT2'!A:A,'B0.SUM (tuần 0)'!$A17) -> 0 | V17: =SUMIFS('B0.4.OEM'!K:K,'B0.4.OEM'!A:A,'B0.SUM (tuần 0)'!$A17) -> 0 | X17: =SUMIFS('B0.8.Online'!K:K,'B0.8.Online'!A:A,'B0.SUM (tuần 0)'!$A17) -> 0 | Y17: =SUM(Z17:AF17) -> 0 | AA17: =SUMIFS('B0.3.XK'!L:L,'B0.3.XK'!A:A,'B0.SUM (tuần 0)'!$A17) -> 0 | AC17: =SUMIFS('B0.5.GT2'!L:L,'B0.5.GT2'!A:A,'B0.SUM (tuần 0)'!$A17) -> 0 | AD17: =SUMIFS('B0.4.OEM'!L:L,'B0.4.OEM'!A:A,'B0.SUM (tuần 0)'!$A17) -> 0 | AF17: =SUMIFS('B0.8.Online'!L:L,'B0.8.Online'!A:A,'B0.SUM (tuần 0)'!$A17) -> 0 | AG17: =SUM(AH17:AN17) -> 0 | AI17: =SUMIFS('B0.3.XK'!M:M,'B0.3.XK'!A:A,'B0.SUM (tuần 0)'!$A17) -> 0 | AK17: =SUMIFS('B0.5.GT2'!M:M,'B0.5.GT2'!A:A,'B0.SUM (tuần 0)'!$A17) -> 0 | AL17: =SUMIFS('B0.4.OEM'!M:M,'B0.4.OEM'!A:A,'B0.SUM (tuần 0)'!$A17) -> 0 | AN17: =SUMIFS('B0.8.Online'!M:M,'B0.8.Online'!A:A,'B0.SUM (tuần 0)'!$A17) -> 0 | AP17: =SUMIFS('B1.SUM (tuần 4)'!$I:$I,'B1.SUM (tuần 4)'!$A:$A,'B0.SUM (tuần 0)'!$A17) -> 0 | AQ17: =I17-AP17 -> 30
A18: 1001040537 | B18: Máy lọc nước KAROFI KAQ-U05 Pro | C18: KAQ-U05 Pro | D18: Máy TCM Sx | E18: 10L | F18: XK | H18: 1310192 | I18: =SUM(J18:P18) -> 0 | K18: =SUMIFS('B0.3.XK'!J:J,'B0.3.XK'!A:A,'B0.SUM (tuần 0)'!$A18) -> 0 | M18: =SUMIFS('B0.5.GT2'!K:K,'B0.5.GT2'!A:A,'B0.SUM (tuần 0)'!$A18) -> 0 | N18: =SUMIFS('B0.4.OEM'!J:J,'B0.4.OEM'!A:A,'B0.SUM (tuần 0)'!$A18) -> 0 | P18: =SUMIFS('B0.8.Online'!J:J,'B0.8.Online'!A:A,'B0.SUM (tuần 0)'!$A18) -> 0 | Q18: =SUM(R18:X18) -> 0 | S18: =SUMIFS('B0.3.XK'!K:K,'B0.3.XK'!A:A,'B0.SUM (tuần 0)'!$A18) -> 0 | U18: =SUMIFS('B0.5.GT2'!K:K,'B0.5.GT2'!A:A,'B0.SUM (tuần 0)'!$A18) -> 0 | V18: =SUMIFS('B0.4.OEM'!K:K,'B0.4.OEM'!A:A,'B0.SUM (tuần 0)'!$A18) -> 0 | X18: =SUMIFS('B0.8.Online'!K:K,'B0.8.Online'!A:A,'B0.SUM (tuần 0)'!$A18) -> 0 | Y18: =SUM(Z18:AF18) -> 0 | AA18: =SUMIFS('B0.3.XK'!L:L,'B0.3.XK'!A:A,'B0.SUM (tuần 0)'!$A18) -> 0 | AC18: =SUMIFS('B0.5.GT2'!L:L,'B0.5.GT2'!A:A,'B0.SUM (tuần 0)'!$A18) -> 0 | AD18: =SUMIFS('B0.4.OEM'!L:L,'B0.4.OEM'!A:A,'B0.SUM (tuần 0)'!$A18) -> 0 | AF18: =SUMIFS('B0.8.Online'!L:L,'B0.8.Online'!A:A,'B0.SUM (tuần 0)'!$A18) -> 0 | AG18: =SUM(AH18:AN18) -> 0 | AI18: =SUMIFS('B0.3.XK'!M:M,'B0.3.XK'!A:A,'B0.SUM (tuần 0)'!$A18) -> 0 | AK18: =SUMIFS('B0.5.GT2'!M:M,'B0.5.GT2'!A:A,'B0.SUM (tuần 0)'!$A18) -> 0 | AL18: =SUMIFS('B0.4.OEM'!M:M,'B0.4.OEM'!A:A,'B0.SUM (tuần 0)'!$A18) -> 0 | AN18: =SUMIFS('B0.8.Online'!M:M,'B0.8.Online'!A:A,'B0.SUM (tuần 0)'!$A18) -> 0 | AP18: =SUMIFS('B1.SUM (tuần 4)'!$I:$I,'B1.SUM (tuần 4)'!$A:$A,'B0.SUM (tuần 0)'!$A18) -> 0 | AQ18: =I18-AP18 -> 0
A19: 1001040549 | B19: Máy lọc nước nóng lạnh KAROFI KAD-X58 | C19: KAD-X58 | D19: Máy TCM Sx | E19: Block | F19: XK | H19: 4505559 | I19: =SUM(J19:P19) -> 0 | K19: =SUMIFS('B0.3.XK'!J:J,'B0.3.XK'!A:A,'B0.SUM (tuần 0)'!$A19) -> 0 | M19: =SUMIFS('B0.5.GT2'!K:K,'B0.5.GT2'!A:A,'B0.SUM (tuần 0)'!$A19) -> 0 | N19: =SUMIFS('B0.4.OEM'!J:J,'B0.4.OEM'!A:A,'B0.SUM (tuần 0)'!$A19) -> 0 | P19: =SUMIFS('B0.8.Online'!J:J,'B0.8.Online'!A:A,'B0.SUM (tuần 0)'!$A19) -> 0 | Q19: =SUM(R19:X19) -> 0 | S19: =SUMIFS('B0.3.XK'!K:K,'B0.3.XK'!A:A,'B0.SUM (tuần 0)'!$A19) -> 0 | U19: =SUMIFS('B0.5.GT2'!K:K,'B0.5.GT2'!A:A,'B0.SUM (tuần 0)'!$A19) -> 0 | V19: =SUMIFS('B0.4.OEM'!K:K,'B0.4.OEM'!A:A,'B0.SUM (tuần 0)'!$A19) -> 0 | X19: =SUMIFS('B0.8.Online'!K:K,'B0.8.Online'!A:A,'B0.SUM (tuần 0)'!$A19) -> 0 | Y19: =SUM(Z19:AF19) -> 20 | AA19: =SUMIFS('B0.3.XK'!L:L,'B0.3.XK'!A:A,'B0.SUM (tuần 0)'!$A19) -> 20 | AC19: =SUMIFS('B0.5.GT2'!L:L,'B0.5.GT2'!A:A,'B0.SUM (tuần 0)'!$A19) -> 0 | AD19: =SUMIFS('B0.4.OEM'!L:L,'B0.4.OEM'!A:A,'B0.SUM (tuần 0)'!$A19) -> 0 | AF19: =SUMIFS('B0.8.Online'!L:L,'B0.8.Online'!A:A,'B0.SUM (tuần 0)'!$A19) -> 0 | AG19: =SUM(AH19:AN19) -> 0 | AI19: =SUMIFS('B0.3.XK'!M:M,'B0.3.XK'!A:A,'B0.SUM (tuần 0)'!$A19) -> 0 | AK19: =SUMIFS('B0.5.GT2'!M:M,'B0.5.GT2'!A:A,'B0.SUM (tuần 0)'!$A19) -> 0 | AL19: =SUMIFS('B0.4.OEM'!M:M,'B0.4.OEM'!A:A,'B0.SUM (tuần 0)'!$A19) -> 0 | AN19: =SUMIFS('B0.8.Online'!M:M,'B0.8.Online'!A:A,'B0.SUM (tuần 0)'!$A19) -> 0 | AP19: =SUMIFS('B1.SUM (tuần 4)'!$I:$I,'B1.SUM (tuần 4)'!$A:$A,'B0.SUM (tuần 0)'!$A19) -> 0 | AQ19: =I19-AP19 -> 0
A20: 1001040625 | B20: Máy LN-NL ion kiềm KRF KAE-S88 PROMAX | C20: S88 Promax | D20: Máy TCM Sx | E20: Block | F20: XK | H20: 13949475 | I20: =SUM(J20:P20) -> 0 | K20: =SUMIFS('B0.3.XK'!J:J,'B0.3.XK'!A:A,'B0.SUM (tuần 0)'!$A20) -> 0 | M20: =SUMIFS('B0.5.GT2'!K:K,'B0.5.GT2'!A:A,'B0.SUM (tuần 0)'!$A20) -> 0 | N20: =SUMIFS('B0.4.OEM'!J:J,'B0.4.OEM'!A:A,'B0.SUM (tuần 0)'!$A20) -> 0 | P20: =SUMIFS('B0.8.Online'!J:J,'B0.8.Online'!A:A,'B0.SUM (tuần 0)'!$A20) -> 0 | Q20: =SUM(R20:X20) -> 0 | S20: =SUMIFS('B0.3.XK'!K:K,'B0.3.XK'!A:A,'B0.SUM (tuần 0)'!$A20) -> 0 | U20: =SUMIFS('B0.5.GT2'!K:K,'B0.5.GT2'!A:A,'B0.SUM (tuần 0)'!$A20) -> 0 | V20: =SUMIFS('B0.4.OEM'!K:K,'B0.4.OEM'!A:A,'B0.SUM (tuần 0)'!$A20) -> 0 | X20: =SUMIFS('B0.8.Online'!K:K,'B0.8.Online'!A:A,'B0.SUM (tuần 0)'!$A20) -> 0 | Y20: =SUM(Z20:AF20) -> 0 | AA20: =SUMIFS('B0.3.XK'!L:L,'B0.3.XK'!A:A,'B0.SUM (tuần 0)'!$A20) -> 0 | AC20: =SUMIFS('B0.5.GT2'!L:L,'B0.5.GT2'!A:A,'B0.SUM (tuần 0)'!$A20) -> 0 | AD20: =SUMIFS('B0.4.OEM'!L:L,'B0.4.OEM'!A:A,'B0.SUM (tuần 0)'!$A20) -> 0 | AF20: =SUMIFS('B0.8.Online'!L:L,'B0.8.Online'!A:A,'B0.SUM (tuần 0)'!$A20) -> 0 | AG20: =SUM(AH20:AN20) -> 0 | AI20: =SUMIFS('B0.3.XK'!M:M,'B0.3.XK'!A:A,'B0.SUM (tuần 0)'!$A20) -> 0 | AK20: =SUMIFS('B0.5.GT2'!M:M,'B0.5.GT2'!A:A,'B0.SUM (tuần 0)'!$A20) -> 0 | AL20: =SUMIFS('B0.4.OEM'!M:M,'B0.4.OEM'!A:A,'B0.SUM (tuần 0)'!$A20) -> 0 | AN20: =SUMIFS('B0.8.Online'!M:M,'B0.8.Online'!A:A,'B0.SUM (tuần 0)'!$A20) -> 0 | AP20: =SUMIFS('B1.SUM (tuần 4)'!$I:$I,'B1.SUM (tuần 4)'!$A:$A,'B0.SUM (tuần 0)'!$A20) -> 0 | AQ20: =I20-AP20 -> 0
A21: 1001040673 | B21: Máy lọc tổng Karofi KTF-P02 (SF-T2) | C21: KTF-P02 | D21: Máy TCM Sx | E21: LK khác | F21: XK | H21: 9968336 | I21: =SUM(J21:P21) -> 0 | K21: =SUMIFS('B0.3.XK'!J:J,'B0.3.XK'!A:A,'B0.SUM (tuần 0)'!$A21) -> 0 | M21: =SUMIFS('B0.5.GT2'!K:K,'B0.5.GT2'!A:A,'B0.SUM (tuần 0)'!$A21) -> 0 | N21: =SUMIFS('B0.4.OEM'!J:J,'B0.4.OEM'!A:A,'B0.SUM (tuần 0)'!$A21) -> 0 | P21: =SUMIFS('B0.8.Online'!J:J,'B0.8.Online'!A:A,'B0.SUM (tuần 0)'!$A21) -> 0 | Q21: =SUM(R21:X21) -> 0 | S21: =SUMIFS('B0.3.XK'!K:K,'B0.3.XK'!A:A,'B0.SUM (tuần 0)'!$A21) -> 0 | U21: =SUMIFS('B0.5.GT2'!K:K,'B0.5.GT2'!A:A,'B0.SUM (tuần 0)'!$A21) -> 0 | V21: =SUMIFS('B0.4.OEM'!K:K,'B0.4.OEM'!A:A,'B0.SUM (tuần 0)'!$A21) -> 0 | X21: =SUMIFS('B0.8.Online'!K:K,'B0.8.Online'!A:A,'B0.SUM (tuần 0)'!$A21) -> 0 | Y21: =SUM(Z21:AF21) -> 0 | AA21: =SUMIFS('B0.3.XK'!L:L,'B0.3.XK'!A:A,'B0.SUM (tuần 0)'!$A21) -> 0 | AC21: =SUMIFS('B0.5.GT2'!L:L,'B0.5.GT2'!A:A,'B0.SUM (tuần 0)'!$A21) -> 0 | AD21: =SUMIFS('B0.4.OEM'!L:L,'B0.4.OEM'!A:A,'B0.SUM (tuần 0)'!$A21) -> 0 | AF21: =SUMIFS('B0.8.Online'!L:L,'B0.8.Online'!A:A,'B0.SUM (tuần 0)'!$A21) -> 0 | AG21: =SUM(AH21:AN21) -> 0 | AI21: =SUMIFS('B0.3.XK'!M:M,'B0.3.XK'!A:A,'B0.SUM (tuần 0)'!$A21) -> 0 | AK21: =SUMIFS('B0.5.GT2'!M:M,'B0.5.GT2'!A:A,'B0.SUM (tuần 0)'!$A21) -> 0 | AL21: =SUMIFS('B0.4.OEM'!M:M,'B0.4.OEM'!A:A,'B0.SUM (tuần 0)'!$A21) -> 0 | AN21: =SUMIFS('B0.8.Online'!M:M,'B0.8.Online'!A:A,'B0.SUM (tuần 0)'!$A21) -> 0 | AP21: =SUMIFS('B1.SUM (tuần 4)'!$I:$I,'B1.SUM (tuần 4)'!$A:$A,'B0.SUM (tuần 0)'!$A21) -> 0 | AQ21: =I21-AP21 -> 0
A22: 1001110006 | B22: MÁY RO-01 Tecomen 7S | C22: RO-01 | D22: Máy TCM Sx | E22: 10L | F22: XK | H22: 1735791 | I22: =SUM(J22:P22) -> 0 | K22: =SUMIFS('B0.3.XK'!J:J,'B0.3.XK'!A:A,'B0.SUM (tuần 0)'!$A22) -> 0 | M22: =SUMIFS('B0.5.GT2'!K:K,'B0.5.GT2'!A:A,'B0.SUM (tuần 0)'!$A22) -> 0 | N22: =SUMIFS('B0.4.OEM'!J:J,'B0.4.OEM'!A:A,'B0.SUM (tuần 0)'!$A22) -> 0 | P22: =SUMIFS('B0.8.Online'!J:J,'B0.8.Online'!A:A,'B0.SUM (tuần 0)'!$A22) -> 0 | Q22: =SUM(R22:X22) -> 0 | S22: =SUMIFS('B0.3.XK'!K:K,'B0.3.XK'!A:A,'B0.SUM (tuần 0)'!$A22) -> 0 | U22: =SUMIFS('B0.5.GT2'!K:K,'B0.5.GT2'!A:A,'B0.SUM (tuần 0)'!$A22) -> 0 | V22: =SUMIFS('B0.4.OEM'!K:K,'B0.4.OEM'!A:A,'B0.SUM (tuần 0)'!$A22) -> 0 | X22: =SUMIFS('B0.8.Online'!K:K,'B0.8.Online'!A:A,'B0.SUM (tuần 0)'!$A22) -> 0 | Y22: =SUM(Z22:AF22) -> 0 | AA22: =SUMIFS('B0.3.XK'!L:L,'B0.3.XK'!A:A,'B0.SUM (tuần 0)'!$A22) -> 0 | AC22: =SUMIFS('B0.5.GT2'!L:L,'B0.5.GT2'!A:A,'B0.SUM (tuần 0)'!$A22) -> 0 | AD22: =SUMIFS('B0.4.OEM'!L:L,'B0.4.OEM'!A:A,'B0.SUM (tuần 0)'!$A22) -> 0 | AF22: =SUMIFS('B0.8.Online'!L:L,'B0.8.Online'!A:A,'B0.SUM (tuần 0)'!$A22) -> 0 | AG22: =SUM(AH22:AN22) -> 0 | AI22: =SUMIFS('B0.3.XK'!M:M,'B0.3.XK'!A:A,'B0.SUM (tuần 0)'!$A22) -> 0 | AK22: =SUMIFS('B0.5.GT2'!M:M,'B0.5.GT2'!A:A,'B0.SUM (tuần 0)'!$A22) -> 0 | AL22: =SUMIFS('B0.4.OEM'!M:M,'B0.4.OEM'!A:A,'B0.SUM (tuần 0)'!$A22) -> 0 | AN22: =SUMIFS('B0.8.Online'!M:M,'B0.8.Online'!A:A,'B0.SUM (tuần 0)'!$A22) -> 0 | AP22: =SUMIFS('B1.SUM (tuần 4)'!$I:$I,'B1.SUM (tuần 4)'!$A:$A,'B0.SUM (tuần 0)'!$A22) -> 0 | AQ22: =I22-AP22 -> 0
A23: 1001110019 | B23: Máy lọc nước UNDERSINK GRANDSAFE | C23: S-S027 | D23: Máy TCM Sx | E23: 10L | F23: XK | H23: 2514694 | I23: =SUM(J23:P23) -> 0 | K23: =SUMIFS('B0.3.XK'!J:J,'B0.3.XK'!A:A,'B0.SUM (tuần 0)'!$A23) -> 0 | M23: =SUMIFS('B0.5.GT2'!K:K,'B0.5.GT2'!A:A,'B0.SUM (tuần 0)'!$A23) -> 0 | N23: =SUMIFS('B0.4.OEM'!J:J,'B0.4.OEM'!A:A,'B0.SUM (tuần 0)'!$A23) -> 0 | P23: =SUMIFS('B0.8.Online'!J:J,'B0.8.Online'!A:A,'B0.SUM (tuần 0)'!$A23) -> 0 | Q23: =SUM(R23:X23) -> 0 | S23: =SUMIFS('B0.3.XK'!K:K,'B0.3.XK'!A:A,'B0.SUM (tuần 0)'!$A23) -> 0 | U23: =SUMIFS('B0.5.GT2'!K:K,'B0.5.GT2'!A:A,'B0.SUM (tuần 0)'!$A23) -> 0 | V23: =SUMIFS('B0.4.OEM'!K:K,'B0.4.OEM'!A:A,'B0.SUM (tuần 0)'!$A23) -> 0 | X23: =SUMIFS('B0.8.Online'!K:K,'B0.8.Online'!A:A,'B0.SUM (tuần 0)'!$A23) -> 0 | Y23: =SUM(Z23:AF23) -> 120 | AA23: =SUMIFS('B0.3.XK'!L:L,'B0.3.XK'!A:A,'B0.SUM (tuần 0)'!$A23) -> 120 | AC23: =SUMIFS('B0.5.GT2'!L:L,'B0.5.GT2'!A:A,'B0.SUM (tuần 0)'!$A23) -> 0 | AD23: =SUMIFS('B0.4.OEM'!L:L,'B0.4.OEM'!A:A,'B0.SUM (tuần 0)'!$A23) -> 0 | AF23: =SUMIFS('B0.8.Online'!L:L,'B0.8.Online'!A:A,'B0.SUM (tuần 0)'!$A23) -> 0 | AG23: =SUM(AH23:AN23) -> 0 | AI23: =SUMIFS('B0.3.XK'!M:M,'B0.3.XK'!A:A,'B0.SUM (tuần 0)'!$A23) -> 0 | AK23: =SUMIFS('B0.5.GT2'!M:M,'B0.5.GT2'!A:A,'B0.SUM (tuần 0)'!$A23) -> 0 | AL23: =SUMIFS('B0.4.OEM'!M:M,'B0.4.OEM'!A:A,'B0.SUM (tuần 0)'!$A23) -> 0 | AN23: =SUMIFS('B0.8.Online'!M:M,'B0.8.Online'!A:A,'B0.SUM (tuần 0)'!$A23) -> 0 | AP23: =SUMIFS('B1.SUM (tuần 4)'!$I:$I,'B1.SUM (tuần 4)'!$A:$A,'B0.SUM (tuần 0)'!$A23) -> 0 | AQ23: =I23-AP23 -> 0
A24: 1001110020 | B24: Máy RO-100 GRANDSAFE | C24: RO-100 | D24: Máy TCM Sx | E24: 10L | F24: XK | H24: 2002968 | I24: =SUM(J24:P24) -> 0 | K24: =SUMIFS('B0.3.XK'!J:J,'B0.3.XK'!A:A,'B0.SUM (tuần 0)'!$A24) -> 0 | M24: =SUMIFS('B0.5.GT2'!K:K,'B0.5.GT2'!A:A,'B0.SUM (tuần 0)'!$A24) -> 0 | N24: =SUMIFS('B0.4.OEM'!J:J,'B0.4.OEM'!A:A,'B0.SUM (tuần 0)'!$A24) -> 0 | P24: =SUMIFS('B0.8.Online'!J:J,'B0.8.Online'!A:A,'B0.SUM (tuần 0)'!$A24) -> 0 | Q24: =SUM(R24:X24) -> 0 | S24: =SUMIFS('B0.3.XK'!K:K,'B0.3.XK'!A:A,'B0.SUM (tuần 0)'!$A24) -> 0 | U24: =SUMIFS('B0.5.GT2'!K:K,'B0.5.GT2'!A:A,'B0.SUM (tuần 0)'!$A24) -> 0 | V24: =SUMIFS('B0.4.OEM'!K:K,'B0.4.OEM'!A:A,'B0.SUM (tuần 0)'!$A24) -> 0 | X24: =SUMIFS('B0.8.Online'!K:K,'B0.8.Online'!A:A,'B0.SUM (tuần 0)'!$A24) -> 0 | Y24: =SUM(Z24:AF24) -> 70 | AA24: =SUMIFS('B0.3.XK'!L:L,'B0.3.XK'!A:A,'B0.SUM (tuần 0)'!$A24) -> 70 | AC24: =SUMIFS('B0.5.GT2'!L:L,'B0.5.GT2'!A:A,'B0.SUM (tuần 0)'!$A24) -> 0 | AD24: =SUMIFS('B0.4.OEM'!L:L,'B0.4.OEM'!A:A,'B0.SUM (tuần 0)'!$A24) -> 0 | AF24: =SUMIFS('B0.8.Online'!L:L,'B0.8.Online'!A:A,'B0.SUM (tuần 0)'!$A24) -> 0 | AG24: =SUM(AH24:AN24) -> 0 | AI24: =SUMIFS('B0.3.XK'!M:M,'B0.3.XK'!A:A,'B0.SUM (tuần 0)'!$A24) -> 0 | AK24: =SUMIFS('B0.5.GT2'!M:M,'B0.5.GT2'!A:A,'B0.SUM (tuần 0)'!$A24) -> 0 | AL24: =SUMIFS('B0.4.OEM'!M:M,'B0.4.OEM'!A:A,'B0.SUM (tuần 0)'!$A24) -> 0 | AN24: =SUMIFS('B0.8.Online'!M:M,'B0.8.Online'!A:A,'B0.SUM (tuần 0)'!$A24) -> 0 | AP24: =SUMIFS('B1.SUM (tuần 4)'!$I:$I,'B1.SUM (tuần 4)'!$A:$A,'B0.SUM (tuần 0)'!$A24) -> 0 | AQ24: =I24-AP24 -> 0
A25: 1001110035 | B25: Máy BCN-400 GPD ANMAX | C25: BCN-400 | D25: Máy TCM Sx | E25: BCN | F25: XK | H25: 4854165 | I25: =SUM(J25:P25) -> 0 | K25: =SUMIFS('B0.3.XK'!J:J,'B0.3.XK'!A:A,'B0.SUM (tuần 0)'!$A25) -> 0 | M25: =SUMIFS('B0.5.GT2'!K:K,'B0.5.GT2'!A:A,'B0.SUM (tuần 0)'!$A25) -> 0 | N25: =SUMIFS('B0.4.OEM'!J:J,'B0.4.OEM'!A:A,'B0.SUM (tuần 0)'!$A25) -> 0 | P25: =SUMIFS('B0.8.Online'!J:J,'B0.8.Online'!A:A,'B0.SUM (tuần 0)'!$A25) -> 0 | Q25: =SUM(R25:X25) -> 0 | S25: =SUMIFS('B0.3.XK'!K:K,'B0.3.XK'!A:A,'B0.SUM (tuần 0)'!$A25) -> 0 | U25: =SUMIFS('B0.5.GT2'!K:K,'B0.5.GT2'!A:A,'B0.SUM (tuần 0)'!$A25) -> 0 | V25: =SUMIFS('B0.4.OEM'!K:K,'B0.4.OEM'!A:A,'B0.SUM (tuần 0)'!$A25) -> 0 | X25: =SUMIFS('B0.8.Online'!K:K,'B0.8.Online'!A:A,'B0.SUM (tuần 0)'!$A25) -> 0 | Y25: =SUM(Z25:AF25) -> 0 | AA25: =SUMIFS('B0.3.XK'!L:L,'B0.3.XK'!A:A,'B0.SUM (tuần 0)'!$A25) -> 0 | AC25: =SUMIFS('B0.5.GT2'!L:L,'B0.5.GT2'!A:A,'B0.SUM (tuần 0)'!$A25) -> 0 | AD25: =SUMIFS('B0.4.OEM'!L:L,'B0.4.OEM'!A:A,'B0.SUM (tuần 0)'!$A25) -> 0 | AF25: =SUMIFS('B0.8.Online'!L:L,'B0.8.Online'!A:A,'B0.SUM (tuần 0)'!$A25) -> 0 | AG25: =SUM(AH25:AN25) -> 300 | AI25: =SUMIFS('B0.3.XK'!M:M,'B0.3.XK'!A:A,'B0.SUM (tuần 0)'!$A25) -> 300 | AK25: =SUMIFS('B0.5.GT2'!M:M,'B0.5.GT2'!A:A,'B0.SUM (tuần 0)'!$A25) -> 0 | AL25: =SUMIFS('B0.4.OEM'!M:M,'B0.4.OEM'!A:A,'B0.SUM (tuần 0)'!$A25) -> 0 | AN25: =SUMIFS('B0.8.Online'!M:M,'B0.8.Online'!A:A,'B0.SUM (tuần 0)'!$A25) -> 0 | AP25: =SUMIFS('B1.SUM (tuần 4)'!$I:$I,'B1.SUM (tuần 4)'!$A:$A,'B0.SUM (tuần 0)'!$A25) -> 0 | AQ25: =I25-AP25 -> 0
... A32: 1001110058 | B32: Máy RO-35 Tecomen (7S) | C32: RO-35 | D32: Máy TCM Sx | E32: 10L | F32: XK | H32: 1723294 | I32: =SUM(J32:P32) -> 0 | K32: =SUMIFS('B0.3.XK'!J:J,'B0.3.XK'!A:A,'B0.SUM (tuần 0)'!$A32) -> 0 | M32: =SUMIFS('B0.5.GT2'!K:K,'B0.5.GT2'!A:A,'B0.SUM (tuần 0)'!$A32) -> 0 | N32: =SUMIFS('B0.4.OEM'!J:J,'B0.4.OEM'!A:A,'B0.SUM (tuần 0)'!$A32) -> 0 | P32: =SUMIFS('B0.8.Online'!J:J,'B0.8.Online'!A:A,'B0.SUM (tuần 0)'!$A32) -> 0 | Q32: =SUM(R32:X32) -> 100 | S32: =SUMIFS('B0.3.XK'!K:K,'B0.3.XK'!A:A,'B0.SUM (tuần 0)'!$A32) -> 100 | U32: =SUMIFS('B0.5.GT2'!K:K,'B0.5.GT2'!A:A,'B0.SUM (tuần 0)'!$A32) -> 0 | V32: =SUMIFS('B0.4.OEM'!K:K,'B0.4.OEM'!A:A,'B0.SUM (tuần 0)'!$A32) -> 0 | X32: =SUMIFS('B0.8.Online'!K:K,'B0.8.Online'!A:A,'B0.SUM (tuần 0)'!$A32) -> 0 | Y32: =SUM(Z32:AF32) -> 0 | AA32: =SUMIFS('B0.3.XK'!L:L,'B0.3.XK'!A:A,'B0.SUM (tuần 0)'!$A32) -> 0 | AC32: =SUMIFS('B0.5.GT2'!L:L,'B0.5.GT2'!A:A,'B0.SUM (tuần 0)'!$A32) -> 0 | AD32: =SUMIFS('B0.4.OEM'!L:L,'B0.4.OEM'!A:A,'B0.SUM (tuần 0)'!$A32) -> 0 | AF32: =SUMIFS('B0.8.Online'!L:L,'B0.8.Online'!A:A,'B0.SUM (tuần 0)'!$A32) -> 0 | AG32: =SUM(AH32:AN32) -> 0 | AI32: =SUMIFS('B0.3.XK'!M:M,'B0.3.XK'!A:A,'B0.SUM (tuần 0)'!$A32) -> 0 | AK32: =SUMIFS('B0.5.GT2'!M:M,'B0.5.GT2'!A:A,'B0.SUM (tuần 0)'!$A32) -> 0 | AL32: =SUMIFS('B0.4.OEM'!M:M,'B0.4.OEM'!A:A,'B0.SUM (tuần 0)'!$A32) -> 0 | AN32: =SUMIFS('B0.8.Online'!M:M,'B0.8.Online'!A:A,'B0.SUM (tuần 0)'!$A32) -> 0 | AP32: =SUMIFS('B1.SUM (tuần 4)'!$I:$I,'B1.SUM (tuần 4)'!$A:$A,'B0.SUM (tuần 0)'!$A32) -> 0 | AQ32: =I32-AP32 -> 0
A33: 1001110083 | B33: Máy lọc nước UNDERSINK đen v3 PURE LIFE | C33: S-S027 | D33: Máy TCM Sx | E33: 10L | F33: XK | H33: 2275801 | I33: =SUM(J33:P33) -> 0 | K33: =SUMIFS('B0.3.XK'!J:J,'B0.3.XK'!A:A,'B0.SUM (tuần 0)'!$A33) -> 0 | M33: =SUMIFS('B0.5.GT2'!K:K,'B0.5.GT2'!A:A,'B0.SUM (tuần 0)'!$A33) -> 0 | N33: =SUMIFS('B0.4.OEM'!J:J,'B0.4.OEM'!A:A,'B0.SUM (tuần 0)'!$A33) -> 0 | P33: =SUMIFS('B0.8.Online'!J:J,'B0.8.Online'!A:A,'B0.SUM (tuần 0)'!$A33) -> 0 | Q33: =SUM(R33:X33) -> 0 | S33: =SUMIFS('B0.3.XK'!K:K,'B0.3.XK'!A:A,'B0.SUM (tuần 0)'!$A33) -> 0 | U33: =SUMIFS('B0.5.GT2'!K:K,'B0.5.GT2'!A:A,'B0.SUM (tuần 0)'!$A33) -> 0 | V33: =SUMIFS('B0.4.OEM'!K:K,'B0.4.OEM'!A:A,'B0.SUM (tuần 0)'!$A33) -> 0 | X33: =SUMIFS('B0.8.Online'!K:K,'B0.8.Online'!A:A,'B0.SUM (tuần 0)'!$A33) -> 0 | Y33: =SUM(Z33:AF33) -> 400 | AA33: =SUMIFS('B0.3.XK'!L:L,'B0.3.XK'!A:A,'B0.SUM (tuần 0)'!$A33) -> 400 | AC33: =SUMIFS('B0.5.GT2'!L:L,'B0.5.GT2'!A:A,'B0.SUM (tuần 0)'!$A33) -> 0 | AD33: =SUMIFS('B0.4.OEM'!L:L,'B0.4.OEM'!A:A,'B0.SUM (tuần 0)'!$A33) -> 0 | AF33: =SUMIFS('B0.8.Online'!L:L,'B0.8.Online'!A:A,'B0.SUM (tuần 0)'!$A33) -> 0 | AG33: =SUM(AH33:AN33) -> 0 | AI33: =SUMIFS('B0.3.XK'!M:M,'B0.3.XK'!A:A,'B0.SUM (tuần 0)'!$A33) -> 0 | AK33: =SUMIFS('B0.5.GT2'!M:M,'B0.5.GT2'!A:A,'B0.SUM (tuần 0)'!$A33) -> 0 | AL33: =SUMIFS('B0.4.OEM'!M:M,'B0.4.OEM'!A:A,'B0.SUM (tuần 0)'!$A33) -> 0 | AN33: =SUMIFS('B0.8.Online'!M:M,'B0.8.Online'!A:A,'B0.SUM (tuần 0)'!$A33) -> 0 | AP33: =SUMIFS('B1.SUM (tuần 4)'!$I:$I,'B1.SUM (tuần 4)'!$A:$A,'B0.SUM (tuần 0)'!$A33) -> 0 | AQ33: =I33-AP33 -> 0
A34: 1001110086 | B34: Bộ lọc thô 1 stage PURE LIFE | C34: Prefilter1S10" | D34: Máy TCM Sx | E34: Bộ lọc thô | F34: XK | H34: 124446 | I34: =SUM(J34:P34) -> 0 | K34: =SUMIFS('B0.3.XK'!J:J,'B0.3.XK'!A:A,'B0.SUM (tuần 0)'!$A34) -> 0 | M34: =SUMIFS('B0.5.GT2'!K:K,'B0.5.GT2'!A:A,'B0.SUM (tuần 0)'!$A34) -> 0 | N34: =SUMIFS('B0.4.OEM'!J:J,'B0.4.OEM'!A:A,'B0.SUM (tuần 0)'!$A34) -> 0 | P34: =SUMIFS('B0.8.Online'!J:J,'B0.8.Online'!A:A,'B0.SUM (tuần 0)'!$A34) -> 0 | Q34: =SUM(R34:X34) -> 0 | S34: =SUMIFS('B0.3.XK'!K:K,'B0.3.XK'!A:A,'B0.SUM (tuần 0)'!$A34) -> 0 | U34: =SUMIFS('B0.5.GT2'!K:K,'B0.5.GT2'!A:A,'B0.SUM (tuần 0)'!$A34) -> 0 | V34: =SUMIFS('B0.4.OEM'!K:K,'B0.4.OEM'!A:A,'B0.SUM (tuần 0)'!$A34) -> 0 | X34: =SUMIFS('B0.8.Online'!K:K,'B0.8.Online'!A:A,'B0.SUM (tuần 0)'!$A34) -> 0 | Y34: =SUM(Z34:AF34) -> 100 | AA34: =SUMIFS('B0.3.XK'!L:L,'B0.3.XK'!A:A,'B0.SUM (tuần 0)'!$A34) -> 100 | AC34: =SUMIFS('B0.5.GT2'!L:L,'B0.5.GT2'!A:A,'B0.SUM (tuần 0)'!$A34) -> 0 | AD34: =SUMIFS('B0.4.OEM'!L:L,'B0.4.OEM'!A:A,'B0.SUM (tuần 0)'!$A34) -> 0 | AF34: =SUMIFS('B0.8.Online'!L:L,'B0.8.Online'!A:A,'B0.SUM (tuần 0)'!$A34) -> 0 | AG34: =SUM(AH34:AN34) -> 0 | AI34: =SUMIFS('B0.3.XK'!M:M,'B0.3.XK'!A:A,'B0.SUM (tuần 0)'!$A34) -> 0 | AK34: =SUMIFS('B0.5.GT2'!M:M,'B0.5.GT2'!A:A,'B0.SUM (tuần 0)'!$A34) -> 0 | AL34: =SUMIFS('B0.4.OEM'!M:M,'B0.4.OEM'!A:A,'B0.SUM (tuần 0)'!$A34) -> 0 | AN34: =SUMIFS('B0.8.Online'!M:M,'B0.8.Online'!A:A,'B0.SUM (tuần 0)'!$A34) -> 0 | AP34: =SUMIFS('B1.SUM (tuần 4)'!$I:$I,'B1.SUM (tuần 4)'!$A:$A,'B0.SUM (tuần 0)'!$A34) -> 0 | AQ34: =I34-AP34 -> 0
A35: 1001110088 | B35: Bộ lọc thô 3 stages Pure Life | C35: Prefilter3S10" | D35: Máy TCM Sx | E35: Bộ lọc thô | F35: XK | H35: 400699 | I35: =SUM(J35:P35) -> 0 | K35: =SUMIFS('B0.3.XK'!J:J,'B0.3.XK'!A:A,'B0.SUM (tuần 0)'!$A35) -> 0 | M35: =SUMIFS('B0.5.GT2'!K:K,'B0.5.GT2'!A:A,'B0.SUM (tuần 0)'!$A35) -> 0 | N35: =SUMIFS('B0.4.OEM'!J:J,'B0.4.OEM'!A:A,'B0.SUM (tuần 0)'!$A35) -> 0 | P35: =SUMIFS('B0.8.Online'!J:J,'B0.8.Online'!A:A,'B0.SUM (tuần 0)'!$A35) -> 0 | Q35: =SUM(R35:X35) -> 0 | S35: =SUMIFS('B0.3.XK'!K:K,'B0.3.XK'!A:A,'B0.SUM (tuần 0)'!$A35) -> 0 | U35: =SUMIFS('B0.5.GT2'!K:K,'B0.5.GT2'!A:A,'B0.SUM (tuần 0)'!$A35) -> 0 | V35: =SUMIFS('B0.4.OEM'!K:K,'B0.4.OEM'!A:A,'B0.SUM (tuần 0)'!$A35) -> 0 | X35: =SUMIFS('B0.8.Online'!K:K,'B0.8.Online'!A:A,'B0.SUM (tuần 0)'!$A35) -> 0 | Y35: =SUM(Z35:AF35) -> 100 | AA35: =SUMIFS('B0.3.XK'!L:L,'B0.3.XK'!A:A,'B0.SUM (tuần 0)'!$A35) -> 100 | AC35: =SUMIFS('B0.5.GT2'!L:L,'B0.5.GT2'!A:A,'B0.SUM (tuần 0)'!$A35) -> 0 | AD35: =SUMIFS('B0.4.OEM'!L:L,'B0.4.OEM'!A:A,'B0.SUM (tuần 0)'!$A35) -> 0 | AF35: =SUMIFS('B0.8.Online'!L:L,'B0.8.Online'!A:A,'B0.SUM (tuần 0)'!$A35) -> 0 | AG35: =SUM(AH35:AN35) -> 0 | AI35: =SUMIFS('B0.3.XK'!M:M,'B0.3.XK'!A:A,'B0.SUM (tuần 0)'!$A35) -> 0 | AK35: =SUMIFS('B0.5.GT2'!M:M,'B0.5.GT2'!A:A,'B0.SUM (tuần 0)'!$A35) -> 0 | AL35: =SUMIFS('B0.4.OEM'!M:M,'B0.4.OEM'!A:A,'B0.SUM (tuần 0)'!$A35) -> 0 | AN35: =SUMIFS('B0.8.Online'!M:M,'B0.8.Online'!A:A,'B0.SUM (tuần 0)'!$A35) -> 0 | AP35: =SUMIFS('B1.SUM (tuần 4)'!$I:$I,'B1.SUM (tuần 4)'!$A:$A,'B0.SUM (tuần 0)'!$A35) -> 0 | AQ35: =I35-AP35 -> 0
A36: 1001110090 | B36: Máy RO BCN-300 Tecomen | C36: BCN-300 | D36: Máy TCM Sx | E36: BCN | F36: XK | H36: 6081518 | I36: =SUM(J36:P36) -> 0 | K36: =SUMIFS('B0.3.XK'!J:J,'B0.3.XK'!A:A,'B0.SUM (tuần 0)'!$A36) -> 0 | M36: =SUMIFS('B0.5.GT2'!K:K,'B0.5.GT2'!A:A,'B0.SUM (tuần 0)'!$A36) -> 0 | N36: =SUMIFS('B0.4.OEM'!J:J,'B0.4.OEM'!A:A,'B0.SUM (tuần 0)'!$A36) -> 0 | P36: =SUMIFS('B0.8.Online'!J:J,'B0.8.Online'!A:A,'B0.SUM (tuần 0)'!$A36) -> 0 | Q36: =SUM(R36:X36) -> 0 | S36: =SUMIFS('B0.3.XK'!K:K,'B0.3.XK'!A:A,'B0.SUM (tuần 0)'!$A36) -> 0 | U36: =SUMIFS('B0.5.GT2'!K:K,'B0.5.GT2'!A:A,'B0.SUM (tuần 0)'!$A36) -> 0 | V36: =SUMIFS('B0.4.OEM'!K:K,'B0.4.OEM'!A:A,'B0.SUM (tuần 0)'!$A36) -> 0 | X36: =SUMIFS('B0.8.Online'!K:K,'B0.8.Online'!A:A,'B0.SUM (tuần 0)'!$A36) -> 0 | Y36: =SUM(Z36:AF36) -> 0 | AA36: =SUMIFS('B0.3.XK'!L:L,'B0.3.XK'!A:A,'B0.SUM (tuần 0)'!$A36) -> 0 | AC36: =SUMIFS('B0.5.GT2'!L:L,'B0.5.GT2'!A:A,'B0.SUM (tuần 0)'!$A36) -> 0 | AD36: =SUMIFS('B0.4.OEM'!L:L,'B0.4.OEM'!A:A,'B0.SUM (tuần 0)'!$A36) -> 0 | AF36: =SUMIFS('B0.8.Online'!L:L,'B0.8.Online'!A:A,'B0.SUM (tuần 0)'!$A36) -> 0 | AG36: =SUM(AH36:AN36) -> 0 | AI36: =SUMIFS('B0.3.XK'!M:M,'B0.3.XK'!A:A,'B0.SUM (tuần 0)'!$A36) -> 0 | AK36: =SUMIFS('B0.5.GT2'!M:M,'B0.5.GT2'!A:A,'B0.SUM (tuần 0)'!$A36) -> 0 | AL36: =SUMIFS('B0.4.OEM'!M:M,'B0.4.OEM'!A:A,'B0.SUM (tuần 0)'!$A36) -> 0 | AN36: =SUMIFS('B0.8.Online'!M:M,'B0.8.Online'!A:A,'B0.SUM (tuần 0)'!$A36) -> 0 | AP36: =SUMIFS('B1.SUM (tuần 4)'!$I:$I,'B1.SUM (tuần 4)'!$A:$A,'B0.SUM (tuần 0)'!$A36) -> 0 | AQ36: =I36-AP36 -> 0
A37: 1001110092 | B37: Máy RO Undersink US | C37: UDSUS | D37: Máy TCM Sx | E37: 10L | F37: XK | H37: 1595034 | I37: =SUM(J37:P37) -> 0 | K37: =SUMIFS('B0.3.XK'!J:J,'B0.3.XK'!A:A,'B0.SUM (tuần 0)'!$A37) -> 0 | M37: =SUMIFS('B0.5.GT2'!K:K,'B0.5.GT2'!A:A,'B0.SUM (tuần 0)'!$A37) -> 0 | N37: =SUMIFS('B0.4.OEM'!J:J,'B0.4.OEM'!A:A,'B0.SUM (tuần 0)'!$A37) -> 0 | P37: =SUMIFS('B0.8.Online'!J:J,'B0.8.Online'!A:A,'B0.SUM (tuần 0)'!$A37) -> 0 | Q37: =SUM(R37:X37) -> 0 | S37: =SUMIFS('B0.3.XK'!K:K,'B0.3.XK'!A:A,'B0.SUM (tuần 0)'!$A37) -> 0 | U37: =SUMIFS('B0.5.GT2'!K:K,'B0.5.GT2'!A:A,'B0.SUM (tuần 0)'!$A37) -> 0 | V37: =SUMIFS('B0.4.OEM'!K:K,'B0.4.OEM'!A:A,'B0.SUM (tuần 0)'!$A37) -> 0 | X37: =SUMIFS('B0.8.Online'!K:K,'B0.8.Online'!A:A,'B0.SUM (tuần 0)'!$A37) -> 0 | Y37: =SUM(Z37:AF37) -> 612 | AA37: =SUMIFS('B0.3.XK'!L:L,'B0.3.XK'!A:A,'B0.SUM (tuần 0)'!$A37) -> 612 | AC37: =SUMIFS('B0.5.GT2'!L:L,'B0.5.GT2'!A:A,'B0.SUM (tuần 0)'!$A37) -> 0 | AD37: =SUMIFS('B0.4.OEM'!L:L,'B0.4.OEM'!A:A,'B0.SUM (tuần 0)'!$A37) -> 0 | AF37: =SUMIFS('B0.8.Online'!L:L,'B0.8.Online'!A:A,'B0.SUM (tuần 0)'!$A37) -> 0 | AG37: =SUM(AH37:AN37) -> 0 | AI37: =SUMIFS('B0.3.XK'!M:M,'B0.3.XK'!A:A,'B0.SUM (tuần 0)'!$A37) -> 0 | AK37: =SUMIFS('B0.5.GT2'!M:M,'B0.5.GT2'!A:A,'B0.SUM (tuần 0)'!$A37) -> 0 | AL37: =SUMIFS('B0.4.OEM'!M:M,'B0.4.OEM'!A:A,'B0.SUM (tuần 0)'!$A37) -> 0 | AN37: =SUMIFS('B0.8.Online'!M:M,'B0.8.Online'!A:A,'B0.SUM (tuần 0)'!$A37) -> 0 | AP37: =SUMIFS('B1.SUM (tuần 4)'!$I:$I,'B1.SUM (tuần 4)'!$A:$A,'B0.SUM (tuần 0)'!$A37) -> 0 | AQ37: =I37-AP37 -> 0
A38: 1001110097 | B38: MÁY BCN-400 GPD GRANDSAFE | C38: BCN-400 | D38: Máy TCM Sx | E38: BCN | F38: XK | H38: 6735318 | I38: =SUM(J38:P38) -> 0 | K38: =SUMIFS('B0.3.XK'!J:J,'B0.3.XK'!A:A,'B0.SUM (tuần 0)'!$A38) -> 0 | M38: =SUMIFS('B0.5.GT2'!K:K,'B0.5.GT2'!A:A,'B0.SUM (tuần 0)'!$A38) -> 0 | N38: =SUMIFS('B0.4.OEM'!J:J,'B0.4.OEM'!A:A,'B0.SUM (tuần 0)'!$A38) -> 0 | P38: =SUMIFS('B0.8.Online'!J:J,'B0.8.Online'!A:A,'B0.SUM (tuần 0)'!$A38) -> 0 | Q38: =SUM(R38:X38) -> 0 | S38: =SUMIFS('B0.3.XK'!K:K,'B0.3.XK'!A:A,'B0.SUM (tuần 0)'!$A38) -> 0 | U38: =SUMIFS('B0.5.GT2'!K:K,'B0.5.GT2'!A:A,'B0.SUM (tuần 0)'!$A38) -> 0 | V38: =SUMIFS('B0.4.OEM'!K:K,'B0.4.OEM'!A:A,'B0.SUM (tuần 0)'!$A38) -> 0 | X38: =SUMIFS('B0.8.Online'!K:K,'B0.8.Online'!A:A,'B0.SUM (tuần 0)'!$A38) -> 0 | Y38: =SUM(Z38:AF38) -> 20 | AA38: =SUMIFS('B0.3.XK'!L:L,'B0.3.XK'!A:A,'B0.SUM (tuần 0)'!$A38) -> 20 | AC38: =SUMIFS('B0.5.GT2'!L:L,'B0.5.GT2'!A:A,'B0.SUM (tuần 0)'!$A38) -> 0 | AD38: =SUMIFS('B0.4.OEM'!L:L,'B0.4.OEM'!A:A,'B0.SUM (tuần 0)'!$A38) -> 0 | AF38: =SUMIFS('B0.8.Online'!L:L,'B0.8.Online'!A:A,'B0.SUM (tuần 0)'!$A38) -> 0 | AG38: =SUM(AH38:AN38) -> 0 | AI38: =SUMIFS('B0.3.XK'!M:M,'B0.3.XK'!A:A,'B0.SUM (tuần 0)'!$A38) -> 0 | AK38: =SUMIFS('B0.5.GT2'!M:M,'B0.5.GT2'!A:A,'B0.SUM (tuần 0)'!$A38) -> 0 | AL38: =SUMIFS('B0.4.OEM'!M:M,'B0.4.OEM'!A:A,'B0.SUM (tuần 0)'!$A38) -> 0 | AN38: =SUMIFS('B0.8.Online'!M:M,'B0.8.Online'!A:A,'B0.SUM (tuần 0)'!$A38) -> 0 | AP38: =SUMIFS('B1.SUM (tuần 4)'!$I:$I,'B1.SUM (tuần 4)'!$A:$A,'B0.SUM (tuần 0)'!$A38) -> 0 | AQ38: =I38-AP38 -> 0
A39: 1001110128 | B39: Bộ lọc thô 2 stages LALANKA | C39: Prefilter2S10" | D39: Máy TCM Sx | E39: Bộ lọc thô | F39: XK | H39: 230474 | I39: =SUM(J39:P39) -> 0 | K39: =SUMIFS('B0.3.XK'!J:J,'B0.3.XK'!A:A,'B0.SUM (tuần 0)'!$A39) -> 0 | M39: =SUMIFS('B0.5.GT2'!K:K,'B0.5.GT2'!A:A,'B0.SUM (tuần 0)'!$A39) -> 0 | N39: =SUMIFS('B0.4.OEM'!J:J,'B0.4.OEM'!A:A,'B0.SUM (tuần 0)'!$A39) -> 0 | P39: =SUMIFS('B0.8.Online'!J:J,'B0.8.Online'!A:A,'B0.SUM (tuần 0)'!$A39) -> 0 | Q39: =SUM(R39:X39) -> 0 | S39: =SUMIFS('B0.3.XK'!K:K,'B0.3.XK'!A:A,'B0.SUM (tuần 0)'!$A39) -> 0 | U39: =SUMIFS('B0.5.GT2'!K:K,'B0.5.GT2'!A:A,'B0.SUM (tuần 0)'!$A39) -> 0 | V39: =SUMIFS('B0.4.OEM'!K:K,'B0.4.OEM'!A:A,'B0.SUM (tuần 0)'!$A39) -> 0 | X39: =SUMIFS('B0.8.Online'!K:K,'B0.8.Online'!A:A,'B0.SUM (tuần 0)'!$A39) -> 0 | Y39: =SUM(Z39:AF39) -> 0 | AA39: =SUMIFS('B0.3.XK'!L:L,'B0.3.XK'!A:A,'B0.SUM (tuần 0)'!$A39) -> 0 | AC39: =SUMIFS('B0.5.GT2'!L:L,'B0.5.GT2'!A:A,'B0.SUM (tuần 0)'!$A39) -> 0 | AD39: =SUMIFS('B0.4.OEM'!L:L,'B0.4.OEM'!A:A,'B0.SUM (tuần 0)'!$A39) -> 0 | AF39: =SUMIFS('B0.8.Online'!L:L,'B0.8.Online'!A:A,'B0.SUM (tuần 0)'!$A39) -> 0 | AG39: =SUM(AH39:AN39) -> 0 | AI39: =SUMIFS('B0.3.XK'!M:M,'B0.3.XK'!A:A,'B0.SUM (tuần 0)'!$A39) -> 0 | AK39: =SUMIFS('B0.5.GT2'!M:M,'B0.5.GT2'!A:A,'B0.SUM (tuần 0)'!$A39) -> 0 | AL39: =SUMIFS('B0.4.OEM'!M:M,'B0.4.OEM'!A:A,'B0.SUM (tuần 0)'!$A39) -> 0 | AN39: =SUMIFS('B0.8.Online'!M:M,'B0.8.Online'!A:A,'B0.SUM (tuần 0)'!$A39) -> 0 | AP39: =SUMIFS('B1.SUM (tuần 4)'!$I:$I,'B1.SUM (tuần 4)'!$A:$A,'B0.SUM (tuần 0)'!$A39) -> 0 | AQ39: =I39-AP39 -> 0
A40: 1001110129 | B40: Bộ lọc thô 3 stages LALANKA | C40: Prefilter3S10" | D40: Máy TCM Sx | E40: Bộ lọc thô | F40: XK | H40: 358866 | I40: =SUM(J40:P40) -> 0 | K40: =SUMIFS('B0.3.XK'!J:J,'B0.3.XK'!A:A,'B0.SUM (tuần 0)'!$A40) -> 0 | M40: =SUMIFS('B0.5.GT2'!K:K,'B0.5.GT2'!A:A,'B0.SUM (tuần 0)'!$A40) -> 0 | N40: =SUMIFS('B0.4.OEM'!J:J,'B0.4.OEM'!A:A,'B0.SUM (tuần 0)'!$A40) -> 0 | P40: =SUMIFS('B0.8.Online'!J:J,'B0.8.Online'!A:A,'B0.SUM (tuần 0)'!$A40) -> 0 | Q40: =SUM(R40:X40) -> 0 | S40: =SUMIFS('B0.3.XK'!K:K,'B0.3.XK'!A:A,'B0.SUM (tuần 0)'!$A40) -> 0 | U40: =SUMIFS('B0.5.GT2'!K:K,'B0.5.GT2'!A:A,'B0.SUM (tuần 0)'!$A40) -> 0 | V40: =SUMIFS('B0.4.OEM'!K:K,'B0.4.OEM'!A:A,'B0.SUM (tuần 0)'!$A40) -> 0 | X40: =SUMIFS('B0.8.Online'!K:K,'B0.8.Online'!A:A,'B0.SUM (tuần 0)'!$A40) -> 0 | Y40: =SUM(Z40:AF40) -> 0 | AA40: =SUMIFS('B0.3.XK'!L:L,'B0.3.XK'!A:A,'B0.SUM (tuần 0)'!$A40) -> 0 | AC40: =SUMIFS('B0.5.GT2'!L:L,'B0.5.GT2'!A:A,'B0.SUM (tuần 0)'!$A40) -> 0 | AD40: =SUMIFS('B0.4.OEM'!L:L,'B0.4.OEM'!A:A,'B0.SUM (tuần 0)'!$A40) -> 0 | AF40: =SUMIFS('B0.8.Online'!L:L,'B0.8.Online'!A:A,'B0.SUM (tuần 0)'!$A40) -> 0 | AG40: =SUM(AH40:AN40) -> 0 | AI40: =SUMIFS('B0.3.XK'!M:M,'B0.3.XK'!A:A,'B0.SUM (tuần 0)'!$A40) -> 0 | AK40: =SUMIFS('B0.5.GT2'!M:M,'B0.5.GT2'!A:A,'B0.SUM (tuần 0)'!$A40) -> 0 | AL40: =SUMIFS('B0.4.OEM'!M:M,'B0.4.OEM'!A:A,'B0.SUM (tuần 0)'!$A40) -> 0 | AN40: =SUMIFS('B0.8.Online'!M:M,'B0.8.Online'!A:A,'B0.SUM (tuần 0)'!$A40) -> 0 | AP40: =SUMIFS('B1.SUM (tuần 4)'!$I:$I,'B1.SUM (tuần 4)'!$A:$A,'B0.SUM (tuần 0)'!$A40) -> 0 | AQ40: =I40-AP40 -> 0
A41: 1001110132 | B41: Máy RO-30 MAXPURE | C41: RO-30 | D41: Máy TCM Sx | E41: 10L | F41: XK | H41: 1447041 | I41: =SUM(J41:P41) -> 0 | K41: =SUMIFS('B0.3.XK'!J:J,'B0.3.XK'!A:A,'B0.SUM (tuần 0)'!$A41) -> 0 | M41: =SUMIFS('B0.5.GT2'!K:K,'B0.5.GT2'!A:A,'B0.SUM (tuần 0)'!$A41) -> 0 | N41: =SUMIFS('B0.4.OEM'!J:J,'B0.4.OEM'!A:A,'B0.SUM (tuần 0)'!$A41) -> 0 | P41: =SUMIFS('B0.8.Online'!J:J,'B0.8.Online'!A:A,'B0.SUM (tuần 0)'!$A41) -> 0 | Q41: =SUM(R41:X41) -> 0 | S41: =SUMIFS('B0.3.XK'!K:K,'B0.3.XK'!A:A,'B0.SUM (tuần 0)'!$A41) -> 0 | U41: =SUMIFS('B0.5.GT2'!K:K,'B0.5.GT2'!A:A,'B0.SUM (tuần 0)'!$A41) -> 0 | V41: =SUMIFS('B0.4.OEM'!K:K,'B0.4.OEM'!A:A,'B0.SUM (tuần 0)'!$A41) -> 0 | X41: =SUMIFS('B0.8.Online'!K:K,'B0.8.Online'!A:A,'B0.SUM (tuần 0)'!$A41) -> 0 | Y41: =SUM(Z41:AF41) -> 500 | AA41: =SUMIFS('B0.3.XK'!L:L,'B0.3.XK'!A:A,'B0.SUM (tuần 0)'!$A41) -> 500 | AC41: =SUMIFS('B0.5.GT2'!L:L,'B0.5.GT2'!A:A,'B0.SUM (tuần 0)'!$A41) -> 0 | AD41: =SUMIFS('B0.4.OEM'!L:L,'B0.4.OEM'!A:A,'B0.SUM (tuần 0)'!$A41) -> 0 | AF41: =SUMIFS('B0.8.Online'!L:L,'B0.8.Online'!A:A,'B0.SUM (tuần 0)'!$A41) -> 0 | AG41: =SUM(AH41:AN41) -> 0 | AI41: =SUMIFS('B0.3.XK'!M:M,'B0.3.XK'!A:A,'B0.SUM (tuần 0)'!$A41) -> 0 | AK41: =SUMIFS('B0.5.GT2'!M:M,'B0.5.GT2'!A:A,'B0.SUM (tuần 0)'!$A41) -> 0 | AL41: =SUMIFS('B0.4.OEM'!M:M,'B0.4.OEM'!A:A,'B0.SUM (tuần 0)'!$A41) -> 0 | AN41: =SUMIFS('B0.8.Online'!M:M,'B0.8.Online'!A:A,'B0.SUM (tuần 0)'!$A41) -> 0 | AP41: =SUMIFS('B1.SUM (tuần 4)'!$I:$I,'B1.SUM (tuần 4)'!$A:$A,'B0.SUM (tuần 0)'!$A41) -> 0 | AQ41: =I41-AP41 -> 0
A42: 1001110139 | B42: Máy lọc nước UNDERSINK AQUA PURE (7S) | C42: S-S027 | D42: Máy TCM Sx | E42: 10L | F42: XK | H42: 2630984 | I42: =SUM(J42:P42) -> 0 | K42: =SUMIFS('B0.3.XK'!J:J,'B0.3.XK'!A:A,'B0.SUM (tuần 0)'!$A42) -> 0 | M42: =SUMIFS('B0.5.GT2'!K:K,'B0.5.GT2'!A:A,'B0.SUM (tuần 0)'!$A42) -> 0 | N42: =SUMIFS('B0.4.OEM'!J:J,'B0.4.OEM'!A:A,'B0.SUM (tuần 0)'!$A42) -> 0 | P42: =SUMIFS('B0.8.Online'!J:J,'B0.8.Online'!A:A,'B0.SUM (tuần 0)'!$A42) -> 0 | Q42: =SUM(R42:X42) -> 0 | S42: =SUMIFS('B0.3.XK'!K:K,'B0.3.XK'!A:A,'B0.SUM (tuần 0)'!$A42) -> 0 | U42: =SUMIFS('B0.5.GT2'!K:K,'B0.5.GT2'!A:A,'B0.SUM (tuần 0)'!$A42) -> 0 | V42: =SUMIFS('B0.4.OEM'!K:K,'B0.4.OEM'!A:A,'B0.SUM (tuần 0)'!$A42) -> 0 | X42: =SUMIFS('B0.8.Online'!K:K,'B0.8.Online'!A:A,'B0.SUM (tuần 0)'!$A42) -> 0 | Y42: =SUM(Z42:AF42) -> 0 | AA42: =SUMIFS('B0.3.XK'!L:L,'B0.3.XK'!A:A,'B0.SUM (tuần 0)'!$A42) -> 0 | AC42: =SUMIFS('B0.5.GT2'!L:L,'B0.5.GT2'!A:A,'B0.SUM (tuần 0)'!$A42) -> 0 | AD42: =SUMIFS('B0.4.OEM'!L:L,'B0.4.OEM'!A:A,'B0.SUM (tuần 0)'!$A42) -> 0 | AF42: =SUMIFS('B0.8.Online'!L:L,'B0.8.Online'!A:A,'B0.SUM (tuần 0)'!$A42) -> 0 | AG42: =SUM(AH42:AN42) -> 0 | AI42: =SUMIFS('B0.3.XK'!M:M,'B0.3.XK'!A:A,'B0.SUM (tuần 0)'!$A42) -> 0 | AK42: =SUMIFS('B0.5.GT2'!M:M,'B0.5.GT2'!A:A,'B0.SUM (tuần 0)'!$A42) -> 0 | AL42: =SUMIFS('B0.4.OEM'!M:M,'B0.4.OEM'!A:A,'B0.SUM (tuần 0)'!$A42) -> 0 | AN42: =SUMIFS('B0.8.Online'!M:M,'B0.8.Online'!A:A,'B0.SUM (tuần 0)'!$A42) -> 0 | AP42: =SUMIFS('B1.SUM (tuần 4)'!$I:$I,'B1.SUM (tuần 4)'!$A:$A,'B0.SUM (tuần 0)'!$A42) -> 0 | AQ42: =I42-AP42 -> 0
A43: 1001110151 | B43: Máy BCN-200 GPD Karofi (NATURAL) | C43: BCN-200 | D43: Máy TCM Sx | E43: BCN | F43: XK | H43: 4612991 | I43: =SUM(J43:P43) -> 0 | K43: =SUMIFS('B0.3.XK'!J:J,'B0.3.XK'!A:A,'B0.SUM (tuần 0)'!$A43) -> 0 | M43: =SUMIFS('B0.5.GT2'!K:K,'B0.5.GT2'!A:A,'B0.SUM (tuần 0)'!$A43) -> 0 | N43: =SUMIFS('B0.4.OEM'!J:J,'B0.4.OEM'!A:A,'B0.SUM (tuần 0)'!$A43) -> 0 | P43: =SUMIFS('B0.8.Online'!J:J,'B0.8.Online'!A:A,'B0.SUM (tuần 0)'!$A43) -> 0 | Q43: =SUM(R43:X43) -> 0 | S43: =SUMIFS('B0.3.XK'!K:K,'B0.3.XK'!A:A,'B0.SUM (tuần 0)'!$A43) -> 0 | U43: =SUMIFS('B0.5.GT2'!K:K,'B0.5.GT2'!A:A,'B0.SUM (tuần 0)'!$A43) -> 0 | V43: =SUMIFS('B0.4.OEM'!K:K,'B0.4.OEM'!A:A,'B0.SUM (tuần 0)'!$A43) -> 0 | X43: =SUMIFS('B0.8.Online'!K:K,'B0.8.Online'!A:A,'B0.SUM (tuần 0)'!$A43) -> 0 | Y43: =SUM(Z43:AF43) -> 0 | AA43: =SUMIFS('B0.3.XK'!L:L,'B0.3.XK'!A:A,'B0.SUM (tuần 0)'!$A43) -> 0 | AC43: =SUMIFS('B0.5.GT2'!L:L,'B0.5.GT2'!A:A,'B0.SUM (tuần 0)'!$A43) -> 0 | AD43: =SUMIFS('B0.4.OEM'!L:L,'B0.4.OEM'!A:A,'B0.SUM (tuần 0)'!$A43) -> 0 | AF43: =SUMIFS('B0.8.Online'!L:L,'B0.8.Online'!A:A,'B0.SUM (tuần 0)'!$A43) -> 0 | AG43: =SUM(AH43:AN43) -> 0 | AI43: =SUMIFS('B0.3.XK'!M:M,'B0.3.XK'!A:A,'B0.SUM (tuần 0)'!$A43) -> 0 | AK43: =SUMIFS('B0.5.GT2'!M:M,'B0.5.GT2'!A:A,'B0.SUM (tuần 0)'!$A43) -> 0 | AL43: =SUMIFS('B0.4.OEM'!M:M,'B0.4.OEM'!A:A,'B0.SUM (tuần 0)'!$A43) -> 0 | AN43: =SUMIFS('B0.8.Online'!M:M,'B0.8.Online'!A:A,'B0.SUM (tuần 0)'!$A43) -> 0 | AP43: =SUMIFS('B1.SUM (tuần 4)'!$I:$I,'B1.SUM (tuần 4)'!$A:$A,'B0.SUM (tuần 0)'!$A43) -> 0 | AQ43: =I43-AP43 -> 0
A44: 1001110152 | B44: Máy BCN-300 GPD Karofi (NATURAL) | C44: BCN-300 | D44: Máy TCM Sx | E44: BCN | F44: XK | H44: 5426403 | I44: =SUM(J44:P44) -> 0 | K44: =SUMIFS('B0.3.XK'!J:J,'B0.3.XK'!A:A,'B0.SUM (tuần 0)'!$A44) -> 0 | M44: =SUMIFS('B0.5.GT2'!K:K,'B0.5.GT2'!A:A,'B0.SUM (tuần 0)'!$A44) -> 0 | N44: =SUMIFS('B0.4.OEM'!J:J,'B0.4.OEM'!A:A,'B0.SUM (tuần 0)'!$A44) -> 0 | P44: =SUMIFS('B0.8.Online'!J:J,'B0.8.Online'!A:A,'B0.SUM (tuần 0)'!$A44) -> 0 | Q44: =SUM(R44:X44) -> 0 | S44: =SUMIFS('B0.3.XK'!K:K,'B0.3.XK'!A:A,'B0.SUM (tuần 0)'!$A44) -> 0 | U44: =SUMIFS('B0.5.GT2'!K:K,'B0.5.GT2'!A:A,'B0.SUM (tuần 0)'!$A44) -> 0 | V44: =SUMIFS('B0.4.OEM'!K:K,'B0.4.OEM'!A:A,'B0.SUM (tuần 0)'!$A44) -> 0 | X44: =SUMIFS('B0.8.Online'!K:K,'B0.8.Online'!A:A,'B0.SUM (tuần 0)'!$A44) -> 0 | Y44: =SUM(Z44:AF44) -> 0 | AA44: =SUMIFS('B0.3.XK'!L:L,'B0.3.XK'!A:A,'B0.SUM (tuần 0)'!$A44) -> 0 | AC44: =SUMIFS('B0.5.GT2'!L:L,'B0.5.GT2'!A:A,'B0.SUM (tuần 0)'!$A44) -> 0 | AD44: =SUMIFS('B0.4.OEM'!L:L,'B0.4.OEM'!A:A,'B0.SUM (tuần 0)'!$A44) -> 0 | AF44: =SUMIFS('B0.8.Online'!L:L,'B0.8.Online'!A:A,'B0.SUM (tuần 0)'!$A44) -> 0 | AG44: =SUM(AH44:AN44) -> 150 | AI44: =SUMIFS('B0.3.XK'!M:M,'B0.3.XK'!A:A,'B0.SUM (tuần 0)'!$A44) -> 150 | AK44: =SUMIFS('B0.5.GT2'!M:M,'B0.5.GT2'!A:A,'B0.SUM (tuần 0)'!$A44) -> 0 | AL44: =SUMIFS('B0.4.OEM'!M:M,'B0.4.OEM'!A:A,'B0.SUM (tuần 0)'!$A44) -> 0 | AN44: =SUMIFS('B0.8.Online'!M:M,'B0.8.Online'!A:A,'B0.SUM (tuần 0)'!$A44) -> 0 | AP44: =SUMIFS('B1.SUM (tuần 4)'!$I:$I,'B1.SUM (tuần 4)'!$A:$A,'B0.SUM (tuần 0)'!$A44) -> 0 | AQ44: =I44-AP44 -> 0
A45: 1001110153 | B45: Máy BCN-400 GPD Karofi (NATURAL) | C45: BCN-400 | D45: Máy TCM Sx | E45: BCN | F45: XK | H45: 5867093 | I45: =SUM(J45:P45) -> 0 | K45: =SUMIFS('B0.3.XK'!J:J,'B0.3.XK'!A:A,'B0.SUM (tuần 0)'!$A45) -> 0 | M45: =SUMIFS('B0.5.GT2'!K:K,'B0.5.GT2'!A:A,'B0.SUM (tuần 0)'!$A45) -> 0 | N45: =SUMIFS('B0.4.OEM'!J:J,'B0.4.OEM'!A:A,'B0.SUM (tuần 0)'!$A45) -> 0 | P45: =SUMIFS('B0.8.Online'!J:J,'B0.8.Online'!A:A,'B0.SUM (tuần 0)'!$A45) -> 0 | Q45: =SUM(R45:X45) -> 0 | S45: =SUMIFS('B0.3.XK'!K:K,'B0.3.XK'!A:A,'B0.SUM (tuần 0)'!$A45) -> 0 | U45: =SUMIFS('B0.5.GT2'!K:K,'B0.5.GT2'!A:A,'B0.SUM (tuần 0)'!$A45) -> 0 | V45: =SUMIFS('B0.4.OEM'!K:K,'B0.4.OEM'!A:A,'B0.SUM (tuần 0)'!$A45) -> 0 | X45: =SUMIFS('B0.8.Online'!K:K,'B0.8.Online'!A:A,'B0.SUM (tuần 0)'!$A45) -> 0 | Y45: =SUM(Z45:AF45) -> 20 | AA45: =SUMIFS('B0.3.XK'!L:L,'B0.3.XK'!A:A,'B0.SUM (tuần 0)'!$A45) -> 20 | AC45: =SUMIFS('B0.5.GT2'!L:L,'B0.5.GT2'!A:A,'B0.SUM (tuần 0)'!$A45) -> 0 | AD45: =SUMIFS('B0.4.OEM'!L:L,'B0.4.OEM'!A:A,'B0.SUM (tuần 0)'!$A45) -> 0 | AF45: =SUMIFS('B0.8.Online'!L:L,'B0.8.Online'!A:A,'B0.SUM (tuần 0)'!$A45) -> 0 | AG45: =SUM(AH45:AN45) -> 0 | AI45: =SUMIFS('B0.3.XK'!M:M,'B0.3.XK'!A:A,'B0.SUM (tuần 0)'!$A45) -> 0 | AK45: =SUMIFS('B0.5.GT2'!M:M,'B0.5.GT2'!A:A,'B0.SUM (tuần 0)'!$A45) -> 0 | AL45: =SUMIFS('B0.4.OEM'!M:M,'B0.4.OEM'!A:A,'B0.SUM (tuần 0)'!$A45) -> 0 | AN45: =SUMIFS('B0.8.Online'!M:M,'B0.8.Online'!A:A,'B0.SUM (tuần 0)'!$A45) -> 0 | AP45: =SUMIFS('B1.SUM (tuần 4)'!$I:$I,'B1.SUM (tuần 4)'!$A:$A,'B0.SUM (tuần 0)'!$A45) -> 0 | AQ45: =I45-AP45 -> 0
A46: 1001110156 | B46: Máy BCN-400 GPD Tecomen | C46: BCN-400 | D46: Máy TCM Sx | E46: BCN | F46: XK | H46: 6850818 | I46: =SUM(J46:P46) -> 0 | K46: =SUMIFS('B0.3.XK'!J:J,'B0.3.XK'!A:A,'B0.SUM (tuần 0)'!$A46) -> 0 | M46: =SUMIFS('B0.5.GT2'!K:K,'B0.5.GT2'!A:A,'B0.SUM (tuần 0)'!$A46) -> 0 | N46: =SUMIFS('B0.4.OEM'!J:J,'B0.4.OEM'!A:A,'B0.SUM (tuần 0)'!$A46) -> 0 | P46: =SUMIFS('B0.8.Online'!J:J,'B0.8.Online'!A:A,'B0.SUM (tuần 0)'!$A46) -> 0 | Q46: =SUM(R46:X46) -> 0 | S46: =SUMIFS('B0.3.XK'!K:K,'B0.3.XK'!A:A,'B0.SUM (tuần 0)'!$A46) -> 0 | U46: =SUMIFS('B0.5.GT2'!K:K,'B0.5.GT2'!A:A,'B0.SUM (tuần 0)'!$A46) -> 0 | V46: =SUMIFS('B0.4.OEM'!K:K,'B0.4.OEM'!A:A,'B0.SUM (tuần 0)'!$A46) -> 0 | X46: =SUMIFS('B0.8.Online'!K:K,'B0.8.Online'!A:A,'B0.SUM (tuần 0)'!$A46) -> 0 | Y46: =SUM(Z46:AF46) -> 0 | AA46: =SUMIFS('B0.3.XK'!L:L,'B0.3.XK'!A:A,'B0.SUM (tuần 0)'!$A46) -> 0 | AC46: =SUMIFS('B0.5.GT2'!L:L,'B0.5.GT2'!A:A,'B0.SUM (tuần 0)'!$A46) -> 0 | AD46: =SUMIFS('B0.4.OEM'!L:L,'B0.4.OEM'!A:A,'B0.SUM (tuần 0)'!$A46) -> 0 | AF46: =SUMIFS('B0.8.Online'!L:L,'B0.8.Online'!A:A,'B0.SUM (tuần 0)'!$A46) -> 0 | AG46: =SUM(AH46:AN46) -> 50 | AI46: =SUMIFS('B0.3.XK'!M:M,'B0.3.XK'!A:A,'B0.SUM (tuần 0)'!$A46) -> 50 | AK46: =SUMIFS('B0.5.GT2'!M:M,'B0.5.GT2'!A:A,'B0.SUM (tuần 0)'!$A46) -> 0 | AL46: =SUMIFS('B0.4.OEM'!M:M,'B0.4.OEM'!A:A,'B0.SUM (tuần 0)'!$A46) -> 0 | AN46: =SUMIFS('B0.8.Online'!M:M,'B0.8.Online'!A:A,'B0.SUM (tuần 0)'!$A46) -> 0 | AP46: =SUMIFS('B1.SUM (tuần 4)'!$I:$I,'B1.SUM (tuần 4)'!$A:$A,'B0.SUM (tuần 0)'!$A46) -> 0 | AQ46: =I46-AP46 -> 0
...

Sheet B0.3.XK
A1: BẢNG 0.3: | B1: SALES FORECAST - KÊNH XUẤT KHẨU | I1: Tổng cộng | O1: Miền Bắc | U1: Miền Nam
I2: TỔNG | J2: =J10 -> Tháng 7 | K2: =K10 -> Tháng 8 | L2: =L10 -> Tháng 9 | M2: =M10 -> Tháng 10
G3: NHÓM 1 | H3: Máy TCM sx | I3: =SUM(J3:M3) -> 27066 | J3: =SUMIF($D$10:$D$1025,$H3,J$10:J$1025) -> 3795 | K3: =SUMIF($D$10:$D$1025,$H3,K$10:K$1025) -> 7150 | L3: =SUMIF($D$10:$D$1025,$H3,L$10:L$1025) -> 7791 | M3: =SUMIF($D$10:$D$1025,$H3,M$10:M$1025) -> 8330
G4: NHÓM 2 | H4: Máy nhập khẩu | I4: =SUM(J4:M4) -> 0 | J4: =SUMIF($D$10:$D$1025,$H4,J$10:J$1025) -> 0 | K4: =SUMIF($D$10:$D$1025,$H4,K$10:K$1025) -> 0 | L4: =SUMIF($D$10:$D$1025,$H4,L$10:L$1025) -> 0 | M4: =SUMIF($D$10:$D$1025,$H4,M$10:M$1025) -> 0
G5: NHÓM 3 | H5: Mockup | I5: =SUM(J5:M5) -> 0 | J5: =SUMIF($D$10:$D$1025,$H5,J$10:J$1025) -> 0 | K5: =SUMIF($D$10:$D$1025,$H5,K$10:K$1025) -> 0 | L5: =SUMIF($D$10:$D$1025,$H5,L$10:L$1025) -> 0 | M5: =SUMIF($D$10:$D$1025,$H5,M$10:M$1025) -> 0
G6: NHÓM 4 | H6: Lõi | I6: =SUM(J6:M6) -> 529105 | J6: =SUMIF($D$10:$D$1025,$H6,J$10:J$1025) -> 134477 | K6: =SUMIF($D$10:$D$1025,$H6,K$10:K$1025) -> 43355 | L6: =SUMIF($D$10:$D$1025,$H6,L$10:L$1025) -> 59130 | M6: =SUMIF($D$10:$D$1025,$H6,M$10:M$1025) -> 292143
G7: NHÓM 5 | H7: Màng | I7: =SUM(J7:M7) -> 11930 | J7: =SUMIF($D$10:$D$1025,$H7,J$10:J$1025) -> 6475 | K7: =SUMIF($D$10:$D$1025,$H7,K$10:K$1025) -> 1975 | L7: =SUMIF($D$10:$D$1025,$H7,L$10:L$1025) -> 1450 | M7: =SUMIF($D$10:$D$1025,$H7,M$10:M$1025) -> 2030
A8: Ngày update | B8: ='B0.SUM (tuần 0)'!B3 -> 46204 | H8: Doanh thu theo FC | J8: =SUMPRODUCT($H$11:$H$715,J11:J715) -> 1.1008535e+10 | K8: =SUMPRODUCT($H$11:$H$176,K11:K176) -> 1.2531411e+10 | L8: =SUMPRODUCT($H$11:$H$176,L11:L176) -> 1.391031e+10 | M8: =SUMPRODUCT($H$11:$H$176,M11:M176) -> 1.2660184e+10
I9: =SUBTOTAL(9,I11:I1013) -> 706434 | J9: =J8*0.6 -> 6.6051212e+09 | K9: =K8*0.6 -> 7.5188466e+09 | L9: =L8*0.6 -> 8.3461863e+09 | M9: =M8*0.6 -> 7.5961102e+09 | O9: =SUBTOTAL(9,O11:O1013) -> 26916 | P9: =SUBTOTAL(9,P11:P1013) -> 169974 | Q9: =SUBTOTAL(9,Q11:Q1013) -> 76475 | R9: =SUBTOTAL(9,R11:R1013) -> 77831 | S9: =SUBTOTAL(9,S11:S1013) -> 382154 | T9: =SUBTOTAL(9,T11:T1013) -> 0 | U9: =SUBTOTAL(9,U11:U1013) -> 0 | V9: =SUBTOTAL(9,V11:V1013) -> 0 | ... Y9: =SUBTOTAL(9,Y11:Y1013) -> 0
